Workbook
Name temp: CourseList!$B$1:$E$14
Name temp: CourseTeacher!#REF!
Name temp_1: CourseList!#REF!
Name temp_1: CourseTeacher!$B$1:$E$13

Sheet CGPA Tabulation Sheet
A1: Shahjalal Uiversity of Science and Technology, Sylhet
A2: Department of English
A3: Session 2011-12
C4: 1st Semester | F4: 2nd Semester | I4: 3rd Semester | L4: Cumulative | O4: Remarks
A7: {=StudentList!B1:B31} -> Student ID | B7: {=StudentList!C1:C31} -> Student's Name | C7: Total Credit | D7: Total GPA | E7: Letter Grade | F7: Total Credit | G7: Total GPA | H7: Letter Grade | I7: Total Credit | J7: Total GPA | K7: Letter Grade | L7: Credit | M7: CGPA | N7: Grade
A8: 2011236001 | B8: Md.Arif Sarkar Bhuiya | C8: {='1st Semester'!AI3:AI32} -> 12 | D8: {='1st Semester'!AJ3:AJ32} -> 4 | E8: =LOOKUP(D8,{0,2,2.25,2.5,2.75,3,3.25,3.5,3.75,4},{"F","C-","C","C+","B-","B","B+","A-","A","A+"}) -> A+ | F8: {='2nd Semester'!AI3:AI32} -> 13 | G8: {='2nd Semester'!AJ3:AJ32} -> 4 | H8: =LOOKUP(G8,{0,2,2.25,2.5,2.75,3,3.25,3.5,3.75,4},{"F","C-","C","C+","B-","B","B+","A-","A","A+"}) -> A+ | I8: {='3rd Semester'!AI3:AI32} -> 11 | J8: {='3rd Semester'!AJ3:AJ32} -> 4 | K8: =LOOKUP(J8,{0,2,2.25,2.5,2.75,3,3.25,3.5,3.75,4},{"F","C-","C","C+","B-","B","B+","A-","A","A+"}) -> A+ | L8: =SUM(C8,F8,I8) -> 36 | M8: =ROUND(SUM(PRODUCT(C8,D8),PRODUCT(F8,G8),PRODUCT(I8,J8))/L8,2) -> 4 | N8: =LOOKUP(M8,{0,2,2.25,2.5,2.75,3,3.25,3.5,3.75,4},{"F","C-","C","C+","B-","B","B+","A-","A","A+"}) -> A+ | O8: =LOOKUP(M8,{0,2,2.25,2.5,2.75,3,3.25,3.5,3.75,4},{"Failed","Passed","Passed","Passed","Passed","Passed","Passed","Passed","Passed with Distinction","Passed with Distinction"}) -> Passed with Distinction
A9: 2011236002 | B9: S.M. Jasim Uddin | C9: 12 | D9: 3.29 | E9: =LOOKUP(D9,{0,2,2.25,2.5,2.75,3,3.25,3.5,3.75,4},{"F","C-","C","C+","B-","B","B+","A-","A","A+"}) -> B+ | F9: 13 | G9: 3.75 | H9: =LOOKUP(G9,{0,2,2.25,2.5,2.75,3,3.25,3.5,3.75,4},{"F","C-","C","C+","B-","B","B+","A-","A","A+"}) -> A | I9: 11 | J9: 3.64 | K9: =LOOKUP(J9,{0,2,2.25,2.5,2.75,3,3.25,3.5,3.75,4},{"F","C-","C","C+","B-","B","B+","A-","A","A+"}) -> A- | L9: =SUM(C9,F9,I9) -> 36 | M9: =ROUND(SUM(PRODUCT(C9,D9),PRODUCT(F9,G9),PRODUCT(I9,J9))/L9,2) -> 3.56 | N9: =LOOKUP(M9,{0,2,2.25,2.5,2.75,3,3.25,3.5,3.75,4},{"F","C-","C","C+","B-","B","B+","A-","A","A+"}) -> A- | O9: =LOOKUP(M9,{0,2,2.25,2.5,2.75,3,3.25,3.5,3.75,4},{"Failed","Passed","Passed","Passed","Passed","Passed","Passed","Passed","Passed with Distinction","Passed with Distinction"}) -> Passed
A10: 2011236003 | B10: Bidyut Jyoti Chakrabarty | C10: 12 | D10: 3.88 | E10: =LOOKUP(D10,{0,2,2.25,2.5,2.75,3,3.25,3.5,3.75,4},{"F","C-","C","C+","B-","B","B+","A-","A","A+"}) -> A | F10: 13 | G10: 3.73 | H10: =LOOKUP(G10,{0,2,2.25,2.5,2.75,3,3.25,3.5,3.75,4},{"F","C-","C","C+","B-","B","B+","A-","A","A+"}) -> A- | I10: 11 | J10: 3.93 | K10: =LOOKUP(J10,{0,2,2.25,2.5,2.75,3,3.25,3.5,3.75,4},{"F","C-","C","C+","B-","B","B+","A-","A","A+"}) -> A | L10: =SUM(C10,F10,I10) -> 36 | M10: =ROUND(SUM(PRODUCT(C10,D10),PRODUCT(F10,G10),PRODUCT(I10,J10))/L10,2) -> 3.84 | N10: =LOOKUP(M10,{0,2,2.25,2.5,2.75,3,3.25,3.5,3.75,4},{"F","C-","C","C+","B-","B","B+","A-","A","A+"}) -> A | O10: =LOOKUP(M10,{0,2,2.25,2.5,2.75,3,3.25,3.5,3.75,4},{"Failed","Passed","Passed","Passed","Passed","Passed","Passed","Passed","Passed with Distinction","Passed with Distinction"}) -> Passed with Distinction
A11: 2011236004 | B11: Md. Shamsuzzaman | C11: 12 | D11: 3.85 | E11: =LOOKUP(D11,{0,2,2.25,2.5,2.75,3,3.25,3.5,3.75,4},{"F","C-","C","C+","B-","B","B+","A-","A","A+"}) -> A | F11: 13 | G11: 3.77 | H11: =LOOKUP(G11,{0,2,2.25,2.5,2.75,3,3.25,3.5,3.75,4},{"F","C-","C","C+","B-","B","B+","A-","A","A+"}) -> A | I11: 11 | J11: 3.84 | K11: =LOOKUP(J11,{0,2,2.25,2.5,2.75,3,3.25,3.5,3.75,4},{"F","C-","C","C+","B-","B","B+","A-","A","A+"}) -> A | L11: =SUM(C11,F11,I11) -> 36 | M11: =ROUND(SUM(PRODUCT(C11,D11),PRODUCT(F11,G11),PRODUCT(I11,J11))/L11,2) -> 3.82 | N11: =LOOKUP(M11,{0,2,2.25,2.5,2.75,3,3.25,3.5,3.75,4},{"F","C-","C","C+","B-","B","B+","A-","A","A+"}) -> A | O11: =LOOKUP(M11,{0,2,2.25,2.5,2.75,3,3.25,3.5,3.75,4},{"Failed","Passed","Passed","Passed","Passed","Passed","Passed","Passed","Passed with Distinction","Passed with Distinction"}) -> Passed with Distinction
A12: 2011236005 | B12: Md.Azad Miah | C12: 12 | D12: 3.92 | E12: =LOOKUP(D12,{0,2,2.25,2.5,2.75,3,3.25,3.5,3.75,4},{"F","C-","C","C+","B-","B","B+","A-","A","A+"}) -> A | F12: 13 | G12: 3.6 | H12: =LOOKUP(G12,{0,2,2.25,2.5,2.75,3,3.25,3.5,3.75,4},{"F","C-","C","C+","B-","B","B+","A-","A","A+"}) -> A- | I12: 11 | J12: 3.5 | K12: =LOOKUP(J12,{0,2,2.25,2.5,2.75,3,3.25,3.5,3.75,4},{"F","C-","C","C+","B-","B","B+","A-","A","A+"}) -> A- | L12: =SUM(C12,F12,I12) -> 36 | M12: =ROUND(SUM(PRODUCT(C12,D12),PRODUCT(F12,G12),PRODUCT(I12,J12))/L12,2) -> 3.68 | N12: =LOOKUP(M12,{0,2,2.25,2.5,2.75,3,3.25,3.5,3.75,4},{"F","C-","C","C+","B-","B","B+","A-","A","A+"}) -> A- | O12: =LOOKUP(M12,{0,2,2.25,2.5,2.75,3,3.25,3.5,3.75,4},{"Failed","Passed","Passed","Passed","Passed","Passed","Passed","Passed","Passed with Distinction","Passed with Distinction"}) -> Passed
A13: 2011236006 | B13: Md. Osman Goni | C13: 12 | D13: 4 | E13: =LOOKUP(D13,{0,2,2.25,2.5,2.75,3,3.25,3.5,3.75,4},{"F","C-","C","C+","B-","B","B+","A-","A","A+"}) -> A+ | F13: 13 | G13: 3.85 | H13: =LOOKUP(G13,{0,2,2.25,2.5,2.75,3,3.25,3.5,3.75,4},{"F","C-","C","C+","B-","B","B+","A-","A","A+"}) -> A | I13: 11 | J13: 3.95 | K13: =LOOKUP(J13,{0,2,2.25,2.5,2.75,3,3.25,3.5,3.75,4},{"F","C-","C","C+","B-","B","B+","A-","A","A+"}) -> A | L13: =SUM(C13,F13,I13) -> 36 | M13: =ROUND(SUM(PRODUCT(C13,D13),PRODUCT(F13,G13),PRODUCT(I13,J13))/L13,2) -> 3.93 | N13: =LOOKUP(M13,{0,2,2.25,2.5,2.75,3,3.25,3.5,3.75,4},{"F","C-","C","C+","B-","B","B+","A-","A","A+"}) -> A | O13: =LOOKUP(M13,{0,2,2.25,2.5,2.75,3,3.25,3.5,3.75,4},{"Failed","Passed","Passed","Passed","Passed","Passed","Passed","Passed","Passed with Distinction","Passed with Distinction"}) -> Passed with Distinction
A14: 2011236007 | B14: S.M. Muakherul Islam | C14: 12 | D14: 3.75 | E14: =LOOKUP(D14,{0,2,2.25,2.5,2.75,3,3.25,3.5,3.75,4},{"F","C-","C","C+","B-","B","B+","A-","A","A+"}) -> A | F14: 13 | G14: 3.81 | H14: =LOOKUP(G14,{0,2,2.25,2.5,2.75,3,3.25,3.5,3.75,4},{"F","C-","C","C+","B-","B","B+","A-","A","A+"}) -> A | I14: 11 | J14: 3.45 | K14: =LOOKUP(J14,{0,2,2.25,2.5,2.75,3,3.25,3.5,3.75,4},{"F","C-","C","C+","B-","B","B+","A-","A","A+"}) -> B+ | L14: =SUM(C14,F14,I14) -> 36 | M14: =ROUND(SUM(PRODUCT(C14,D14),PRODUCT(F14,G14),PRODUCT(I14,J14))/L14,2) -> 3.68 | N14: =LOOKUP(M14,{0,2,2.25,2.5,2.75,3,3.25,3.5,3.75,4},{"F","C-","C","C+","B-","B","B+","A-","A","A+"}) -> A- | O14: =LOOKUP(M14,{0,2,2.25,2.5,2.75,3,3.25,3.5,3.75,4},{"Failed","Passed","Passed","Passed","Passed","Passed","Passed","Passed","Passed with Distinction","Passed with Distinction"}) -> Passed
A15: 2011236008 | B15: Md.Habib-Al-Islam Miah | C15: 12 | D15: 3.67 | E15: =LOOKUP(D15,{0,2,2.25,2.5,2.75,3,3.25,3.5,3.75,4},{"F","C-","C","C+","B-","B","B+","A-","A","A+"}) -> A- | F15: 13 | G15: 3.77 | H15: =LOOKUP(G15,{0,2,2.25,2.5,2.75,3,3.25,3.5,3.75,4},{"F","C-","C","C+","B-","B","B+","A-","A","A+"}) -> A | I15: 11 | J15: 3.86 | K15: =LOOKUP(J15,{0,2,2.25,2.5,2.75,3,3.25,3.5,3.75,4},{"F","C-","C","C+","B-","B","B+","A-","A","A+"}) -> A | L15: =SUM(C15,F15,I15) -> 36 | M15: =ROUND(SUM(PRODUCT(C15,D15),PRODUCT(F15,G15),PRODUCT(I15,J15))/L15,2) -> 3.76 | N15: =LOOKUP(M15,{0,2,2.25,2.5,2.75,3,3.25,3.5,3.75,4},{"F","C-","C","C+","B-","B","B+","A-","A","A+"}) -> A | O15: =LOOKUP(M15,{0,2,2.25,2.5,2.75,3,3.25,3.5,3.75,4},{"Failed","Passed","Passed","Passed","Passed","Passed","Passed","Passed","Passed with Distinction","Passed with Distinction"}) -> Passed with Distinction
A16: 2011236009 | B16: Kazi Jahurul Islam | C16: 12 | D16: 3.69 | E16: =LOOKUP(D16,{0,2,2.25,2.5,2.75,3,3.25,3.5,3.75,4},{"F","C-","C","C+","B-","B","B+","A-","A","A+"}) -> A- | F16: 13 | G16: 3.46 | H16: =LOOKUP(G16,{0,2,2.25,2.5,2.75,3,3.25,3.5,3.75,4},{"F","C-","C","C+","B-","B","B+","A-","A","A+"}) -> B+ | I16: 11 | J16: 3.68 | K16: =LOOKUP(J16,{0,2,2.25,2.5,2.75,3,3.25,3.5,3.75,4},{"F","C-","C","C+","B-","B","B+","A-","A","A+"}) -> A- | L16: =SUM(C16,F16,I16) -> 36 | M16: =ROUND(SUM(PRODUCT(C16,D16),PRODUCT(F16,G16),PRODUCT(I16,J16))/L16,2) -> 3.6 | N16: =LOOKUP(M16,{0,2,2.25,2.5,2.75,3,3.25,3.5,3.75,4},{"F","C-","C","C+","B-","B","B+","A-","A","A+"}) -> A- | O16: =LOOKUP(M16,{0,2,2.25,2.5,2.75,3,3.25,3.5,3.75,4},{"Failed","Passed","Passed","Passed","Passed","Passed","Passed","Passed","Passed with Distinction","Passed with Distinction"}) -> Passed
A17: 2011236010 | B17: Md.Juber Rahman | C17: 12 | D17: 4 | E17: =LOOKUP(D17,{0,2,2.25,2.5,2.75,3,3.25,3.5,3.75,4},{"F","C-","C","C+","B-","B","B+","A-","A","A+"}) -> A+ | F17: 13 | G17: 3.54 | H17: =LOOKUP(G17,{0,2,2.25,2.5,2.75,3,3.25,3.5,3.75,4},{"F","C-","C","C+","B-","B","B+","A-","A","A+"}) -> A- | I17: 11 | J17: 3.27 | K17: =LOOKUP(J17,{0,2,2.25,2.5,2.75,3,3.25,3.5,3.75,4},{"F","C-","C","C+","B-","B","B+","A-","A","A+"}) -> B+ | L17: =SUM(C17,F17,I17) -> 36 | M17: =ROUND(SUM(PRODUCT(C17,D17),PRODUCT(F17,G17),PRODUCT(I17,J17))/L17,2) -> 3.61 | N17: =LOOKUP(M17,{0,2,2.25,2.5,2.75,3,3.25,3.5,3.75,4},{"F","C-","C","C+","B-","B","B+","A-","A","A+"}) -> A- | O17: =LOOKUP(M17,{0,2,2.25,2.5,2.75,3,3.25,3.5,3.75,4},{"Failed","Passed","Passed","Passed","Passed","Passed","Passed","Passed","Passed with Distinction","Passed with Distinction"}) -> Passed
A18: 2011236011 | B18: Md.Emdadur Rahman | C18: 12 | D18: 4 | E18: =LOOKUP(D18,{0,2,2.25,2.5,2.75,3,3.25,3.5,3.75,4},{"F","C-","C","C+","B-","B","B+","A-","A","A+"}) -> A+ | F18: 13 | G18: 3.85 | H18: =LOOKUP(G18,{0,2,2.25,2.5,2.75,3,3.25,3.5,3.75,4},{"F","C-","C","C+","B-","B","B+","A-","A","A+"}) -> A | I18: 11 | J18: 3.77 | K18: =LOOKUP(J18,{0,2,2.25,2.5,2.75,3,3.25,3.5,3.75,4},{"F","C-","C","C+","B-","B","B+","A-","A","A+"}) -> A | L18: =SUM(C18,F18,I18) -> 36 | M18: =ROUND(SUM(PRODUCT(C18,D18),PRODUCT(F18,G18),PRODUCT(I18,J18))/L18,2) -> 3.88 | N18: =LOOKUP(M18,{0,2,2.25,2.5,2.75,3,3.25,3.5,3.75,4},{"F","C-","C","C+","B-","B","B+","A-","A","A+"}) -> A | O18: =LOOKUP(M18,{0,2,2.25,2.5,2.75,3,3.25,3.5,3.75,4},{"Failed","Passed","Passed","Passed","Passed","Passed","Passed","Passed","Passed with Distinction","Passed with Distinction"}) -> Passed with Distinction
A19: 2011236012 | B19: Niranjan Chandra Bhowmik | C19: 12 | D19: 4 | E19: =LOOKUP(D19,{0,2,2.25,2.5,2.75,3,3.25,3.5,3.75,4},{"F","C-","C","C+","B-","B","B+","A-","A","A+"}) -> A+ | F19: 13 | G19: 4 | H19: =LOOKUP(G19,{0,2,2.25,2.5,2.75,3,3.25,3.5,3.75,4},{"F","C-","C","C+","B-","B","B+","A-","A","A+"}) -> A+ | I19: 11 | J19: 4 | K19: =LOOKUP(J19,{0,2,2.25,2.5,2.75,3,3.25,3.5,3.75,4},{"F","C-","C","C+","B-","B","B+","A-","A","A+"}) -> A+ | L19: =SUM(C19,F19,I19) -> 36 | M19: =ROUND(SUM(PRODUCT(C19,D19),PRODUCT(F19,G19),PRODUCT(I19,J19))/L19,2) -> 4 | N19: =LOOKUP(M19,{0,2,2.25,2.5,2.75,3,3.25,3.5,3.75,4},{"F","C-","C","C+","B-","B","B+","A-","A","A+"}) -> A+ | O19: =LOOKUP(M19,{0,2,2.25,2.5,2.75,3,3.25,3.5,3.75,4},{"Failed","Passed","Passed","Passed","Passed","Passed","Passed","Passed","Passed with Distinction","Passed with Distinction"}) -> Passed with Distinction
A20: 2011236013 | B20: Tanwir Osman Ahsan | C20: 12 | D20: 4 | E20: =LOOKUP(D20,{0,2,2.25,2.5,2.75,3,3.25,3.5,3.75,4},{"F","C-","C","C+","B-","B","B+","A-","A","A+"}) -> A+ | F20: 13 | G20: 3.83 | H20: =LOOKUP(G20,{0,2,2.25,2.5,2.75,3,3.25,3.5,3.75,4},{"F","C-","C","C+","B-","B","B+","A-","A","A+"}) -> A | I20: 11 | J20: 3.77 | K20: =LOOKUP(J20,{0,2,2.25,2.5,2.75,3,3.25,3.5,3.75,4},{"F","C-","C","C+","B-","B","B+","A-","A","A+"}) -> A | L20: =SUM(C20,F20,I20) -> 36 | M20: =ROUND(SUM(PRODUCT(C20,D20),PRODUCT(F20,G20),PRODUCT(I20,J20))/L20,2) -> 3.87 | N20: =LOOKUP(M20,{0,2,2.25,2.5,2.75,3,3.25,3.5,3.75,4},{"F","C-","C","C+","B-","B","B+","A-","A","A+"}) -> A | O20: =LOOKUP(M20,{0,2,2.25,2.5,2.75,3,3.25,3.5,3.75,4},{"Failed","Passed","Passed","Passed","Passed","Passed","Passed","Passed","Passed with Distinction","Passed with Distinction"}) -> Passed with Distinction
... A37: 2011236030 | B37: Swity Sultana Monni | C37: 12 | D37: 3.31 | E37: =LOOKUP(D37,{0,2,2.25,2.5,2.75,3,3.25,3.5,3.75,4},{"F","C-","C","C+","B-","B","B+","A-","A","A+"}) -> B+ | F37: 13 | G37: 3.75 | H37: =LOOKUP(G37,{0,2,2.25,2.5,2.75,3,3.25,3.5,3.75,4},{"F","C-","C","C+","B-","B","B+","A-","A","A+"}) -> A | I37: 11 | J37: 3.61 | K37: =LOOKUP(J37,{0,2,2.25,2.5,2.75,3,3.25,3.5,3.75,4},{"F","C-","C","C+","B-","B","B+","A-","A","A+"}) -> A- | L37: =SUM(C37,F37,I37) -> 36 | M37: =ROUND(SUM(PRODUCT(C37,D37),PRODUCT(F37,G37),PRODUCT(I37,J37))/L37,2) -> 3.56 | N37: =LOOKUP(M37,{0,2,2.25,2.5,2.75,3,3.25,3.5,3.75,4},{"F","C-","C","C+","B-","B","B+","A-","A","A+"}) -> A- | O37: =LOOKUP(M37,{0,2,2.25,2.5,2.75,3,3.25,3.5,3.75,4},{"Failed","Passed","Passed","Passed","Passed","Passed","Passed","Passed","Passed with Distinction","Passed with Distinction"}) -> Passed

Sheet StudentList
A1: S.I. | B1: Student ID | C1: Student's Name | D1: Father's Name | E1: Mother's Name
A2: 1 | B2: 2011236001 | C2: Md.Arif Sarkar Bhuiya | D2: Md.Firuj Sarkar | E2: Rokeya Begum
A3: 2 | B3: 2011236002 | C3: S.M. Jasim Uddin | D3: SK. Abdul Malek | E3: Mouludara Begum
A4: 3 | B4: 2011236003 | C4: Bidyut Jyoti Chakrabarty | D4: Beni Madhab Chakrabarty | E4: Gita Rani Chakrabarty
A5: 4 | B5: 2011236004 | C5: Md. Shamsuzzaman | D5: Late Forman Ali | E5: Hamida Begum
A6: 5 | B6: 2011236005 | C6: Md.Azad Miah | D6: Md. Ali Akbar | E6: Minara Begum
A7: 6 | B7: 2011236006 | C7: Md. Osman Goni | D7: Md. Azgor Ali | E7: Hameda Begum
A8: 7 | B8: 2011236007 | C8: S.M. Muakherul Islam | D8: S.M. Ali Abu Rayhan | E8: Ayesha Rayhan
A9: 8 | B9: 2011236008 | C9: Md.Habib-Al-Islam Miah | D9: Md.Shahanoor Islam Miah | E9: Sayeda Hena Islam
A10: 9 | B10: 2011236009 | C10: Kazi Jahurul Islam | D10: Kazi Md. Jalil | E10: Shahanaz Parvin
A11: 10 | B11: 2011236010 | C11: Md.Juber Rahman | D11: Md. Mujibur Rahman | E11: Hasna Begum
A12: 11 | B12: 2011236011 | C12: Md.Emdadur Rahman | D12: Md. Abdul Goffer | E12: Most. Sakera Begum
A13: 12 | B13: 2011236012 | C13: Niranjan Chandra Bhowmik | D13: Sukumar Chandra Bhowmik | E13: Khelon Rani
... A31: 30 | B31: 2011236030 | C31: Swity Sultana Monni | D31: Saleh Ahmed | E31: Rokeya Begum

Sheet CourseList
A1: Semester | B1: Course ID | C1: Course Title | D1: Class/Hour | E1: Credit
A2: 1 | B2: ENG-111 | C2: Introduction to Literature | D2: 33*2 | E2: 3
B3: ENG-113 | C3: Poetry Course | D3: 33*2 | E3: 4
B4: ENG-115 | C4: Essay Writing | D4: 33*2 | E4: 3
B5: ENG-117 | C5: History of English Literature | D5: 33*2 | E5: 2
A6: 2 | B6: ENG-211 | C6: Elizabethan and Jacobean Poetry | D6: 33*2 | E6: 4
B7: ENG-213 | C7: American Drama | D7: 33*2 | E7: 3
B8: ENG-215 | C8: British Fiction | D8: 33*2 | E8: 4
B9: ENG-217 | C9: Introduction to Western Philosophy | D9: 33*2 | E9: 2
A10: 3 | B10: ENG-311 | C10: Semiotics | D10: 33*2 | E10: 3
B11: ENG-315 | C11: Irish Drama | D11: 33*2 | E11: 2
B12: ENG-313 | C12: British Novel | D12: 33*2 | E12: 2
B13: ENG-300 | C13: Monograph and Viva Voce | D13: 33*2 | E13: 4
C15: Total Credits | E15: =SUM(E2:E14) -> 36

Sheet CourseTeacher
A1: Semester | B1: =CourseList!B1 -> Course ID | C1: Assigned Teacher | D1: Code | E1: Designation and Department
A2: 1 | B2: =CourseList!B2 -> ENG-111 | C2: Sabir Ismail | D2: SI | E2: Lecturer, ENG Department
B3: =CourseList!B3 -> ENG-113 | C3: Sayma Sultana Chowdhury | D3: SSC | E3: Lecturer, ENG Department
B4: =CourseList!B4 -> ENG-115 | C4: Md Saiful Islam | D4: MSI | E4: Lecturer, ENG Department
B5: =CourseList!B5 -> ENG-117 | C5: Asif Mohammed Samir | D5: AMS | E5: Lecturer, ENG Department
A6: 2 | B6: =CourseList!B6 -> ENG-211 | C6: Sheikh Nabil Mohammad | D6: SNM | E6: Lecturer, ENG Department
B7: =CourseList!B7 -> ENG-213 | C7: Sayma Sultana Chowdhury | D7: SSC | E7: Lecturer, ENG Department
B8: =CourseList!B8 -> ENG-215 | C8: Biswa Prio Chakrabarty | D8: BPC | E8: Lecturer, ENG Department
B9: =CourseList!B9 -> ENG-217 | C9: Asif Mohammed Samir | D9: AMS | E9: Lecturer, ENG Department
A10: 3 | B10: =CourseList!B10 -> ENG-311 | C10: Sayma Sultana Chowdhury | D10: SSC | E10: Lecturer, ENG Department
B11: =CourseList!B11 -> ENG-315 | C11: Biswa Prio Chakrabarty | D11: BPC | E11: Lecturer, ENG Department
B12: =CourseList!B12 -> ENG-313 | C12: Asif Mohammed Samir | D12: AMS | E12: Lecturer, ENG Department
B13: =CourseList!B13 -> ENG-300 | C13: Asif Mohammed Samir | D13: AMS | E13: Lecturer, ENG Department

Sheet 1st Semester
C1: =CourseList!B2 -> ENG-111 | K1: =CourseList!B3 -> ENG-113 | S1: =CourseList!B4 -> ENG-115 | AA1: =CourseList!B5 -> ENG-117 | AI1: Total Credit | AJ1: Total GPA | AK1: Letter Grade
A2: Serial | B2: {=StudentList!B1:B31} -> Student ID | C2: TT (20) | D2: Final (70) | E2: Attendence (33) | F2: Total | G2: Credit | H2: Letter Grade | I2: GPA | K2: TT (20) | L2: Final (70) | M2: Attendence (33) | N2: Total | O2: Credit | P2: Letter Grade | Q2: GPA | S2: TT (20) | T2: Final (70) | U2: Attendence (33) | V2: Total | W2: Credit | X2: Letter Grade | Y2: GPA | AA2: TT (20) | AB2: Final (70) | AC2: Attendence (33) | AD2: Total | AE2: Credit | AF2: Letter Grade | AG2: GPA
A3: 1 | B3: 2011236001 | C3: 20 | D3: 65 | E3: 30 | F3: =SUM(C3,D3,IF(E3>29,10,IF(E3>26,9,IF(E3>23,8,IF(E3>20,7,IF(E3>17,6,0)))))) -> 95 | G3: 3 | H3: =LOOKUP(F3,{0,40,45,50,55,60,65,70,75,80,100},{"F","C-","C","C+","B-","B","B+","A-","A","A+","Invalid Entry"}) -> A+ | I3: =LOOKUP(F3,{0,40,45,50,55,60,65,70,75,80,100},{0,2,2.25,2.5,2.75,3,3.25,3.5,3.75,4,"Invalid Entry"}) -> 4 | K3: 19 | L3: 63 | M3: 30 | N3: =SUM(K3,L3,IF(M3>29,10,IF(M3>26,9,IF(M3>23,8,IF(M3>20,7,IF(M3>17,6,0)))))) -> 92 | O3: 4 | P3: =LOOKUP(N3,{0,40,45,50,55,60,65,70,75,80,100},{"F","C-","C","C+","B-","B","B+","A-","A","A+","Invalid Entry"}) -> A+ | Q3: =LOOKUP(N3,{0,40,45,50,55,60,65,70,75,80,100},{0,2,2.25,2.5,2.75,3,3.25,3.5,3.75,4,"Invalid Entry"}) -> 4 | S3: 20 | T3: 63 | U3: 30 | V3: =SUM(S3,T3,IF(U3>29,10,IF(U3>26,9,IF(U3>23,8,IF(U3>20,7,IF(U3>17,6,0)))))) -> 93 | W3: 3 | X3: =LOOKUP(V3,{0,40,45,50,55,60,65,70,75,80,100},{"F","C-","C","C+","B-","B","B+","A-","A","A+","Invalid Entry"}) -> A+ | Y3: =LOOKUP(V3,{0,40,45,50,55,60,65,70,75,80,100},{0,2,2.25,2.5,2.75,3,3.25,3.5,3.75,4,"Invalid Entry"}) -> 4 | AA3: 17 | AB3: 63 | AC3: 30 | AD3: =SUM(AA3,AB3,IF(AC3>29,10,IF(AC3>26,9,IF(AC3>23,8,IF(AC3>20,7,IF(AC3>17,6,0)))))) -> 90 | AE3: 2 | AF3: =LOOKUP(AD3,{0,40,45,50,55,60,65,70,75,80,100},{"F","C-","C","C+","B-","B","B+","A-","A","A+","Invalid Entry"}) -> A+ | AG3: =LOOKUP(AD3,{0,40,45,50,55,60,65,70,75,80,100},{0,2,2.25,2.5,2.75,3,3.25,3.5,3.75,4,"Invalid Entry"}) -> 4 | AI3: =SUM(G3,O3,W3,AE3) -> 12 | AJ3: =ROUND(SUM(PRODUCT(I3,G3),PRODUCT(Q3,O3),PRODUCT(Y3,W3),PRODUCT(AG3,AE3))/AI3,2) -> 4 | AK3: =LOOKUP(AJ3,{0,2,2.25,2.5,2.75,3,3.25,3.5,3.75,4},{"F","C-","C","C+","B-","B","B+","A-","A","A+"}) -> A+
A4: 2 | B4: 2011236002 | C4: 11 | D4: 40 | E4: 30 | F4: =SUM(C4,D4,IF(E4>29,10,IF(E4>26,9,IF(E4>23,8,IF(E4>20,7,IF(E4>17,6,0)))))) -> 61 | G4: 3 | H4: =LOOKUP(F4,{0,40,45,50,55,60,65,70,75,80,100},{"F","C-","C","C+","B-","B","B+","A-","A","A+","Invalid Entry"}) -> B | I4: =LOOKUP(F4,{0,40,45,50,55,60,65,70,75,80,100},{0,2,2.25,2.5,2.75,3,3.25,3.5,3.75,4,"Invalid Entry"}) -> 3 | K4: 12 | L4: 45 | M4: 30 | N4: =SUM(K4,L4,IF(M4>29,10,IF(M4>26,9,IF(M4>23,8,IF(M4>20,7,IF(M4>17,6,0)))))) -> 67 | O4: 4 | P4: =LOOKUP(N4,{0,40,45,50,55,60,65,70,75,80,100},{"F","C-","C","C+","B-","B","B+","A-","A","A+","Invalid Entry"}) -> B+ | Q4: =LOOKUP(N4,{0,40,45,50,55,60,65,70,75,80,100},{0,2,2.25,2.5,2.75,3,3.25,3.5,3.75,4,"Invalid Entry"}) -> 3.25 | S4: 15 | T4: 45 | U4: 30 | V4: =SUM(S4,T4,IF(U4>29,10,IF(U4>26,9,IF(U4>23,8,IF(U4>20,7,IF(U4>17,6,0)))))) -> 70 | W4: 3 | X4: =LOOKUP(V4,{0,40,45,50,55,60,65,70,75,80,100},{"F","C-","C","C+","B-","B","B+","A-","A","A+","Invalid Entry"}) -> A- | Y4: =LOOKUP(V4,{0,40,45,50,55,60,65,70,75,80,100},{0,2,2.25,2.5,2.75,3,3.25,3.5,3.75,4,"Invalid Entry"}) -> 3.5 | AA4: 18 | AB4: 45 | AC4: 30 | AD4: =SUM(AA4,AB4,IF(AC4>29,10,IF(AC4>26,9,IF(AC4>23,8,IF(AC4>20,7,IF(AC4>17,6,0)))))) -> 73 | AE4: 2 | AF4: =LOOKUP(AD4,{0,40,45,50,55,60,65,70,75,80,100},{"F","C-","C","C+","B-","B","B+","A-","A","A+","Invalid Entry"}) -> A- | AG4: =LOOKUP(AD4,{0,40,45,50,55,60,65,70,75,80,100},{0,2,2.25,2.5,2.75,3,3.25,3.5,3.75,4,"Invalid Entry"}) -> 3.5 | AI4: =SUM(G4,O4,W4,AE4) -> 12 | AJ4: =ROUND(SUM(PRODUCT(I4,G4),PRODUCT(Q4,O4),PRODUCT(Y4,W4),PRODUCT(AG4,AE4))/AI4,2) -> 3.29 | AK4: =LOOKUP(AJ4,{0,2,2.25,2.5,2.75,3,3.25,3.5,3.75,4},{"F","C-","C","C+","B-","B","B+","A-","A","A+"}) -> B+
A5: 3 | B5: 2011236003 | C5: 19 | D5: 67 | E5: 26 | F5: =SUM(C5,D5,IF(E5>29,10,IF(E5>26,9,IF(E5>23,8,IF(E5>20,7,IF(E5>17,6,0)))))) -> 94 | G5: 3 | H5: =LOOKUP(F5,{0,40,45,50,55,60,65,70,75,80,100},{"F","C-","C","C+","B-","B","B+","A-","A","A+","Invalid Entry"}) -> A+ | I5: =LOOKUP(F5,{0,40,45,50,55,60,65,70,75,80,100},{0,2,2.25,2.5,2.75,3,3.25,3.5,3.75,4,"Invalid Entry"}) -> 4 | K5: 13 | L5: 57 | M5: 26 | N5: =SUM(K5,L5,IF(M5>29,10,IF(M5>26,9,IF(M5>23,8,IF(M5>20,7,IF(M5>17,6,0)))))) -> 78 | O5: 4 | P5: =LOOKUP(N5,{0,40,45,50,55,60,65,70,75,80,100},{"F","C-","C","C+","B-","B","B+","A-","A","A+","Invalid Entry"}) -> A | Q5: =LOOKUP(N5,{0,40,45,50,55,60,65,70,75,80,100},{0,2,2.25,2.5,2.75,3,3.25,3.5,3.75,4,"Invalid Entry"}) -> 3.75 | S5: 20 | T5: 57 | U5: 26 | V5: =SUM(S5,T5,IF(U5>29,10,IF(U5>26,9,IF(U5>23,8,IF(U5>20,7,IF(U5>17,6,0)))))) -> 85 | W5: 3 | X5: =LOOKUP(V5,{0,40,45,50,55,60,65,70,75,80,100},{"F","C-","C","C+","B-","B","B+","A-","A","A+","Invalid Entry"}) -> A+ | Y5: =LOOKUP(V5,{0,40,45,50,55,60,65,70,75,80,100},{0,2,2.25,2.5,2.75,3,3.25,3.5,3.75,4,"Invalid Entry"}) -> 4 | AA5: 11 | AB5: 57 | AC5: 26 | AD5: =SUM(AA5,AB5,IF(AC5>29,10,IF(AC5>26,9,IF(AC5>23,8,IF(AC5>20,7,IF(AC5>17,6,0)))))) -> 76 | AE5: 2 | AF5: =LOOKUP(AD5,{0,40,45,50,55,60,65,70,75,80,100},{"F","C-","C","C+","B-","B","B+","A-","A","A+","Invalid Entry"}) -> A | AG5: =LOOKUP(AD5,{0,40,45,50,55,60,65,70,75,80,100},{0,2,2.25,2.5,2.75,3,3.25,3.5,3.75,4,"Invalid Entry"}) -> 3.75 | AI5: =SUM(G5,O5,W5,AE5) -> 12 | AJ5: =ROUND(SUM(PRODUCT(I5,G5),PRODUCT(Q5,O5),PRODUCT(Y5,W5),PRODUCT(AG5,AE5))/AI5,2) -> 3.88 | AK5: =LOOKUP(AJ5,{0,2,2.25,2.5,2.75,3,3.25,3.5,3.75,4},{"F","C-","C","C+","B-","B","B+","A-","A","A+"}) -> A
A6: 4 | B6: 2011236004 | C6: 15 | D6: 55 | E6: 31 | F6: =SUM(C6,D6,IF(E6>29,10,IF(E6>26,9,IF(E6>23,8,IF(E6>20,7,IF(E6>17,6,0)))))) -> 80 | G6: 3 | H6: =LOOKUP(F6,{0,40,45,50,55,60,65,70,75,80,100},{"F","C-","C","C+","B-","B","B+","A-","A","A+","Invalid Entry"}) -> A+ | I6: =LOOKUP(F6,{0,40,45,50,55,60,65,70,75,80,100},{0,2,2.25,2.5,2.75,3,3.25,3.5,3.75,4,"Invalid Entry"}) -> 4 | K6: 14 | L6: 55 | M6: 31 | N6: =SUM(K6,L6,IF(M6>29,10,IF(M6>26,9,IF(M6>23,8,IF(M6>20,7,IF(M6>17,6,0)))))) -> 79 | O6: 4 | P6: =LOOKUP(N6,{0,40,45,50,55,60,65,70,75,80,100},{"F","C-","C","C+","B-","B","B+","A-","A","A+","Invalid Entry"}) -> A | Q6: =LOOKUP(N6,{0,40,45,50,55,60,65,70,75,80,100},{0,2,2.25,2.5,2.75,3,3.25,3.5,3.75,4,"Invalid Entry"}) -> 3.75 | S6: 10 | T6: 55 | U6: 31 | V6: =SUM(S6,T6,IF(U6>29,10,IF(U6>26,9,IF(U6>23,8,IF(U6>20,7,IF(U6>17,6,0)))))) -> 75 | W6: 3 | X6: =LOOKUP(V6,{0,40,45,50,55,60,65,70,75,80,100},{"F","C-","C","C+","B-","B","B+","A-","A","A+","Invalid Entry"}) -> A | Y6: =LOOKUP(V6,{0,40,45,50,55,60,65,70,75,80,100},{0,2,2.25,2.5,2.75,3,3.25,3.5,3.75,4,"Invalid Entry"}) -> 3.75 | AA6: 16 | AB6: 55 | AC6: 31 | AD6: =SUM(AA6,AB6,IF(AC6>29,10,IF(AC6>26,9,IF(AC6>23,8,IF(AC6>20,7,IF(AC6>17,6,0)))))) -> 81 | AE6: 2 | AF6: =LOOKUP(AD6,{0,40,45,50,55,60,65,70,75,80,100},{"F","C-","C","C+","B-","B","B+","A-","A","A+","Invalid Entry"}) -> A+ | AG6: =LOOKUP(AD6,{0,40,45,50,55,60,65,70,75,80,100},{0,2,2.25,2.5,2.75,3,3.25,3.5,3.75,4,"Invalid Entry"}) -> 4 | AI6: =SUM(G6,O6,W6,AE6) -> 12 | AJ6: =ROUND(SUM(PRODUCT(I6,G6),PRODUCT(Q6,O6),PRODUCT(Y6,W6),PRODUCT(AG6,AE6))/AI6,2) -> 3.85 | AK6: =LOOKUP(AJ6,{0,2,2.25,2.5,2.75,3,3.25,3.5,3.75,4},{"F","C-","C","C+","B-","B","B+","A-","A","A+"}) -> A
A7: 5 | B7: 2011236005 | C7: 19 | D7: 56 | E7: 25 | F7: =SUM(C7,D7,IF(E7>29,10,IF(E7>26,9,IF(E7>23,8,IF(E7>20,7,IF(E7>17,6,0)))))) -> 83 | G7: 3 | H7: =LOOKUP(F7,{0,40,45,50,55,60,65,70,75,80,100},{"F","C-","C","C+","B-","B","B+","A-","A","A+","Invalid Entry"}) -> A+ | I7: =LOOKUP(F7,{0,40,45,50,55,60,65,70,75,80,100},{0,2,2.25,2.5,2.75,3,3.25,3.5,3.75,4,"Invalid Entry"}) -> 4 | K7: 19 | L7: 56 | M7: 25 | N7: =SUM(K7,L7,IF(M7>29,10,IF(M7>26,9,IF(M7>23,8,IF(M7>20,7,IF(M7>17,6,0)))))) -> 83 | O7: 4 | P7: =LOOKUP(N7,{0,40,45,50,55,60,65,70,75,80,100},{"F","C-","C","C+","B-","B","B+","A-","A","A+","Invalid Entry"}) -> A+ | Q7: =LOOKUP(N7,{0,40,45,50,55,60,65,70,75,80,100},{0,2,2.25,2.5,2.75,3,3.25,3.5,3.75,4,"Invalid Entry"}) -> 4 | S7: 17 | T7: 56 | U7: 25 | V7: =SUM(S7,T7,IF(U7>29,10,IF(U7>26,9,IF(U7>23,8,IF(U7>20,7,IF(U7>17,6,0)))))) -> 81 | W7: 3 | X7: =LOOKUP(V7,{0,40,45,50,55,60,65,70,75,80,100},{"F","C-","C","C+","B-","B","B+","A-","A","A+","Invalid Entry"}) -> A+ | Y7: =LOOKUP(V7,{0,40,45,50,55,60,65,70,75,80,100},{0,2,2.25,2.5,2.75,3,3.25,3.5,3.75,4,"Invalid Entry"}) -> 4 | AA7: 10 | AB7: 56 | AC7: 25 | AD7: =SUM(AA7,AB7,IF(AC7>29,10,IF(AC7>26,9,IF(AC7>23,8,IF(AC7>20,7,IF(AC7>17,6,0)))))) -> 74 | AE7: 2 | AF7: =LOOKUP(AD7,{0,40,45,50,55,60,65,70,75,80,100},{"F","C-","C","C+","B-","B","B+","A-","A","A+","Invalid Entry"}) -> A- | AG7: =LOOKUP(AD7,{0,40,45,50,55,60,65,70,75,80,100},{0,2,2.25,2.5,2.75,3,3.25,3.5,3.75,4,"Invalid Entry"}) -> 3.5 | AI7: =SUM(G7,O7,W7,AE7) -> 12 | AJ7: =ROUND(SUM(PRODUCT(I7,G7),PRODUCT(Q7,O7),PRODUCT(Y7,W7),PRODUCT(AG7,AE7))/AI7,2) -> 3.92 | AK7: =LOOKUP(AJ7,{0,2,2.25,2.5,2.75,3,3.25,3.5,3.75,4},{"F","C-","C","C+","B-","B","B+","A-","A","A+"}) -> A
A8: 6 | B8: 2011236006 | C8: 14 | D8: 62 | E8: 21 | F8: =SUM(C8,D8,IF(E8>29,10,IF(E8>26,9,IF(E8>23,8,IF(E8>20,7,IF(E8>17,6,0)))))) -> 83 | G8: 3 | H8: =LOOKUP(F8,{0,40,45,50,55,60,65,70,75,80,100},{"F","C-","C","C+","B-","B","B+","A-","A","A+","Invalid Entry"}) -> A+ | I8: =LOOKUP(F8,{0,40,45,50,55,60,65,70,75,80,100},{0,2,2.25,2.5,2.75,3,3.25,3.5,3.75,4,"Invalid Entry"}) -> 4 | K8: 18 | L8: 62 | M8: 21 | N8: =SUM(K8,L8,IF(M8>29,10,IF(M8>26,9,IF(M8>23,8,IF(M8>20,7,IF(M8>17,6,0)))))) -> 87 | O8: 4 | P8: =LOOKUP(N8,{0,40,45,50,55,60,65,70,75,80,100},{"F","C-","C","C+","B-","B","B+","A-","A","A+","Invalid Entry"}) -> A+ | Q8: =LOOKUP(N8,{0,40,45,50,55,60,65,70,75,80,100},{0,2,2.25,2.5,2.75,3,3.25,3.5,3.75,4,"Invalid Entry"}) -> 4 | S8: 13 | T8: 62 | U8: 21 | V8: =SUM(S8,T8,IF(U8>29,10,IF(U8>26,9,IF(U8>23,8,IF(U8>20,7,IF(U8>17,6,0)))))) -> 82 | W8: 3 | X8: =LOOKUP(V8,{0,40,45,50,55,60,65,70,75,80,100},{"F","C-","C","C+","B-","B","B+","A-","A","A+","Invalid Entry"}) -> A+ | Y8: =LOOKUP(V8,{0,40,45,50,55,60,65,70,75,80,100},{0,2,2.25,2.5,2.75,3,3.25,3.5,3.75,4,"Invalid Entry"}) -> 4 | AA8: 14 | AB8: 62 | AC8: 21 | AD8: =SUM(AA8,AB8,IF(AC8>29,10,IF(AC8>26,9,IF(AC8>23,8,IF(AC8>20,7,IF(AC8>17,6,0)))))) -> 83 | AE8: 2 | AF8: =LOOKUP(AD8,{0,40,45,50,55,60,65,70,75,80,100},{"F","C-","C","C+","B-","B","B+","A-","A","A+","Invalid Entry"}) -> A+ | AG8: =LOOKUP(AD8,{0,40,45,50,55,60,65,70,75,80,100},{0,2,2.25,2.5,2.75,3,3.25,3.5,3.75,4,"Invalid Entry"}) -> 4 | AI8: =SUM(G8,O8,W8,AE8) -> 12 | AJ8: =ROUND(SUM(PRODUCT(I8,G8),PRODUCT(Q8,O8),PRODUCT(Y8,W8),PRODUCT(AG8,AE8))/AI8,2) -> 4 | AK8: =LOOKUP(AJ8,{0,2,2.25,2.5,2.75,3,3.25,3.5,3.75,4},{"F","C-","C","C+","B-","B","B+","A-","A","A+"}) -> A+
A9: 7 | B9: 2011236007 | C9: 10 | D9: 54 | E9: 31 | F9: =SUM(C9,D9,IF(E9>29,10,IF(E9>26,9,IF(E9>23,8,IF(E9>20,7,IF(E9>17,6,0)))))) -> 74 | G9: 3 | H9: =LOOKUP(F9,{0,40,45,50,55,60,65,70,75,80,100},{"F","C-","C","C+","B-","B","B+","A-","A","A+","Invalid Entry"}) -> A- | I9: =LOOKUP(F9,{0,40,45,50,55,60,65,70,75,80,100},{0,2,2.25,2.5,2.75,3,3.25,3.5,3.75,4,"Invalid Entry"}) -> 3.5 | K9: 18 | L9: 54 | M9: 31 | N9: =SUM(K9,L9,IF(M9>29,10,IF(M9>26,9,IF(M9>23,8,IF(M9>20,7,IF(M9>17,6,0)))))) -> 82 | O9: 4 | P9: =LOOKUP(N9,{0,40,45,50,55,60,65,70,75,80,100},{"F","C-","C","C+","B-","B","B+","A-","A","A+","Invalid Entry"}) -> A+ | Q9: =LOOKUP(N9,{0,40,45,50,55,60,65,70,75,80,100},{0,2,2.25,2.5,2.75,3,3.25,3.5,3.75,4,"Invalid Entry"}) -> 4 | S9: 20 | T9: 54 | U9: 31 | V9: =SUM(S9,T9,IF(U9>29,10,IF(U9>26,9,IF(U9>23,8,IF(U9>20,7,IF(U9>17,6,0)))))) -> 84 | W9: 3 | X9: =LOOKUP(V9,{0,40,45,50,55,60,65,70,75,80,100},{"F","C-","C","C+","B-","B","B+","A-","A","A+","Invalid Entry"}) -> A+ | Y9: =LOOKUP(V9,{0,40,45,50,55,60,65,70,75,80,100},{0,2,2.25,2.5,2.75,3,3.25,3.5,3.75,4,"Invalid Entry"}) -> 4 | AA9: 5 | AB9: 54 | AC9: 31 | AD9: =SUM(AA9,AB9,IF(AC9>29,10,IF(AC9>26,9,IF(AC9>23,8,IF(AC9>20,7,IF(AC9>17,6,0)))))) -> 69 | AE9: 2 | AF9: =LOOKUP(AD9,{0,40,45,50,55,60,65,70,75,80,100},{"F","C-","C","C+","B-","B","B+","A-","A","A+","Invalid Entry"}) -> B+ | AG9: =LOOKUP(AD9,{0,40,45,50,55,60,65,70,75,80,100},{0,2,2.25,2.5,2.75,3,3.25,3.5,3.75,4,"Invalid Entry"}) -> 3.25 | AI9: =SUM(G9,O9,W9,AE9) -> 12 | AJ9: =ROUND(SUM(PRODUCT(I9,G9),PRODUCT(Q9,O9),PRODUCT(Y9,W9),PRODUCT(AG9,AE9))/AI9,2) -> 3.75 | AK9: =LOOKUP(AJ9,{0,2,2.25,2.5,2.75,3,3.25,3.5,3.75,4},{"F","C-","C","C+","B-","B","B+","A-","A","A+"}) -> A
A10: 8 | B10: 2011236008 | C10: 18 | D10: 51 | E10: 30 | F10: =SUM(C10,D10,IF(E10>29,10,IF(E10>26,9,IF(E10>23,8,IF(E10>20,7,IF(E10>17,6,0)))))) -> 79 | G10: 3 | H10: =LOOKUP(F10,{0,40,45,50,55,60,65,70,75,80,100},{"F","C-","C","C+","B-","B","B+","A-","A","A+","Invalid Entry"}) -> A | I10: =LOOKUP(F10,{0,40,45,50,55,60,65,70,75,80,100},{0,2,2.25,2.5,2.75,3,3.25,3.5,3.75,4,"Invalid Entry"}) -> 3.75 | K10: 15 | L10: 51 | M10: 30 | N10: =SUM(K10,L10,IF(M10>29,10,IF(M10>26,9,IF(M10>23,8,IF(M10>20,7,IF(M10>17,6,0)))))) -> 76 | O10: 4 | P10: =LOOKUP(N10,{0,40,45,50,55,60,65,70,75,80,100},{"F","C-","C","C+","B-","B","B+","A-","A","A+","Invalid Entry"}) -> A | Q10: =LOOKUP(N10,{0,40,45,50,55,60,65,70,75,80,100},{0,2,2.25,2.5,2.75,3,3.25,3.5,3.75,4,"Invalid Entry"}) -> 3.75 | S10: 17 | T10: 51 | U10: 30 | V10: =SUM(S10,T10,IF(U10>29,10,IF(U10>26,9,IF(U10>23,8,IF(U10>20,7,IF(U10>17,6,0)))))) -> 78 | W10: 3 | X10: =LOOKUP(V10,{0,40,45,50,55,60,65,70,75,80,100},{"F","C-","C","C+","B-","B","B+","A-","A","A+","Invalid Entry"}) -> A | Y10: =LOOKUP(V10,{0,40,45,50,55,60,65,70,75,80,100},{0,2,2.25,2.5,2.75,3,3.25,3.5,3.75,4,"Invalid Entry"}) -> 3.75 | AA10: 7 | AB10: 51 | AC10: 30 | AD10: =SUM(AA10,AB10,IF(AC10>29,10,IF(AC10>26,9,IF(AC10>23,8,IF(AC10>20,7,IF(AC10>17,6,0)))))) -> 68 | AE10: 2 | AF10: =LOOKUP(AD10,{0,40,45,50,55,60,65,70,75,80,100},{"F","C-","C","C+","B-","B","B+","A-","A","A+","Invalid Entry"}) -> B+ | AG10: =LOOKUP(AD10,{0,40,45,50,55,60,65,70,75,80,100},{0,2,2.25,2.5,2.75,3,3.25,3.5,3.75,4,"Invalid Entry"}) -> 3.25 | AI10: =SUM(G10,O10,W10,AE10) -> 12 | AJ10: =ROUND(SUM(PRODUCT(I10,G10),PRODUCT(Q10,O10),PRODUCT(Y10,W10),PRODUCT(AG10,AE10))/AI10,2) -> 3.67 | AK10: =LOOKUP(AJ10,{0,2,2.25,2.5,2.75,3,3.25,3.5,3.75,4},{"F","C-","C","C+","B-","B","B+","A-","A","A+"}) -> A-
A11: 9 | B11: 2011236009 | C11: 9 | D11: 54 | E11: 33 | F11: =SUM(C11,D11,IF(E11>29,10,IF(E11>26,9,IF(E11>23,8,IF(E11>20,7,IF(E11>17,6,0)))))) -> 73 | G11: 3 | H11: =LOOKUP(F11,{0,40,45,50,55,60,65,70,75,80,100},{"F","C-","C","C+","B-","B","B+","A-","A","A+","Invalid Entry"}) -> A- | I11: =LOOKUP(F11,{0,40,45,50,55,60,65,70,75,80,100},{0,2,2.25,2.5,2.75,3,3.25,3.5,3.75,4,"Invalid Entry"}) -> 3.5 | K11: 12 | L11: 54 | M11: 33 | N11: =SUM(K11,L11,IF(M11>29,10,IF(M11>26,9,IF(M11>23,8,IF(M11>20,7,IF(M11>17,6,0)))))) -> 76 | O11: 4 | P11: =LOOKUP(N11,{0,40,45,50,55,60,65,70,75,80,100},{"F","C-","C","C+","B-","B","B+","A-","A","A+","Invalid Entry"}) -> A | Q11: =LOOKUP(N11,{0,40,45,50,55,60,65,70,75,80,100},{0,2,2.25,2.5,2.75,3,3.25,3.5,3.75,4,"Invalid Entry"}) -> 3.75 | S11: 13 | T11: 54 | U11: 33 | V11: =SUM(S11,T11,IF(U11>29,10,IF(U11>26,9,IF(U11>23,8,IF(U11>20,7,IF(U11>17,6,0)))))) -> 77 | W11: 3 | X11: =LOOKUP(V11,{0,40,45,50,55,60,65,70,75,80,100},{"F","C-","C","C+","B-","B","B+","A-","A","A+","Invalid Entry"}) -> A | Y11: =LOOKUP(V11,{0,40,45,50,55,60,65,70,75,80,100},{0,2,2.25,2.5,2.75,3,3.25,3.5,3.75,4,"Invalid Entry"}) -> 3.75 | AA11: 14 | AB11: 54 | AC11: 33 | AD11: =SUM(AA11,AB11,IF(AC11>29,10,IF(AC11>26,9,IF(AC11>23,8,IF(AC11>20,7,IF(AC11>17,6,0)))))) -> 78 | AE11: 2 | AF11: =LOOKUP(AD11,{0,40,45,50,55,60,65,70,75,80,100},{"F","C-","C","C+","B-","B","B+","A-","A","A+","Invalid Entry"}) -> A | AG11: =LOOKUP(AD11,{0,40,45,50,55,60,65,70,75,80,100},{0,2,2.25,2.5,2.75,3,3.25,3.5,3.75,4,"Invalid Entry"}) -> 3.75 | AI11: =SUM(G11,O11,W11,AE11) -> 12 | AJ11: =ROUND(SUM(PRODUCT(I11,G11),PRODUCT(Q11,O11),PRODUCT(Y11,W11),PRODUCT(AG11,AE11))/AI11,2) -> 3.69 | AK11: =LOOKUP(AJ11,{0,2,2.25,2.5,2.75,3,3.25,3.5,3.75,4},{"F","C-","C","C+","B-","B","B+","A-","A","A+"}) -> A-
A12: 10 | B12: 2011236010 | C12: 16 | D12: 70 | E12: 24 | F12: =SUM(C12,D12,IF(E12>29,10,IF(E12>26,9,IF(E12>23,8,IF(E12>20,7,IF(E12>17,6,0)))))) -> 94 | G12: 3 | H12: =LOOKUP(F12,{0,40,45,50,55,60,65,70,75,80,100},{"F","C-","C","C+","B-","B","B+","A-","A","A+","Invalid Entry"}) -> A+ | I12: =LOOKUP(F12,{0,40,45,50,55,60,65,70,75,80,100},{0,2,2.25,2.5,2.75,3,3.25,3.5,3.75,4,"Invalid Entry"}) -> 4 | K12: 10 | L12: 70 | M12: 24 | N12: =SUM(K12,L12,IF(M12>29,10,IF(M12>26,9,IF(M12>23,8,IF(M12>20,7,IF(M12>17,6,0)))))) -> 88 | O12: 4 | P12: =LOOKUP(N12,{0,40,45,50,55,60,65,70,75,80,100},{"F","C-","C","C+","B-","B","B+","A-","A","A+","Invalid Entry"}) -> A+ | Q12: =LOOKUP(N12,{0,40,45,50,55,60,65,70,75,80,100},{0,2,2.25,2.5,2.75,3,3.25,3.5,3.75,4,"Invalid Entry"}) -> 4 | S12: 15 | T12: 70 | U12: 24 | V12: =SUM(S12,T12,IF(U12>29,10,IF(U12>26,9,IF(U12>23,8,IF(U12>20,7,IF(U12>17,6,0)))))) -> 93 | W12: 3 | X12: =LOOKUP(V12,{0,40,45,50,55,60,65,70,75,80,100},{"F","C-","C","C+","B-","B","B+","A-","A","A+","Invalid Entry"}) -> A+ | Y12: =LOOKUP(V12,{0,40,45,50,55,60,65,70,75,80,100},{0,2,2.25,2.5,2.75,3,3.25,3.5,3.75,4,"Invalid Entry"}) -> 4 | AA12: 10 | AB12: 70 | AC12: 24 | AD12: =SUM(AA12,AB12,IF(AC12>29,10,IF(AC12>26,9,IF(AC12>23,8,IF(AC12>20,7,IF(AC12>17,6,0)))))) -> 88 | AE12: 2 | AF12: =LOOKUP(AD12,{0,40,45,50,55,60,65,70,75,80,100},{"F","C-","C","C+","B-","B","B+","A-","A","A+","Invalid Entry"}) -> A+ | AG12: =LOOKUP(AD12,{0,40,45,50,55,60,65,70,75,80,100},{0,2,2.25,2.5,2.75,3,3.25,3.5,3.75,4,"Invalid Entry"}) -> 4 | AI12: =SUM(G12,O12,W12,AE12) -> 12 | AJ12: =ROUND(SUM(PRODUCT(I12,G12),PRODUCT(Q12,O12),PRODUCT(Y12,W12),PRODUCT(AG12,AE12))/AI12,2) -> 4 | AK12: =LOOKUP(AJ12,{0,2,2.25,2.5,2.75,3,3.25,3.5,3.75,4},{"F","C-","C","C+","B-","B","B+","A-","A","A+"}) -> A+
A13: 11 | B13: 2011236011 | C13: 16 | D13: 66 | E13: 31 | F13: =SUM(C13,D13,IF(E13>29,10,IF(E13>26,9,IF(E13>23,8,IF(E13>20,7,IF(E13>17,6,0)))))) -> 92 | G13: 3 | H13: =LOOKUP(F13,{0,40,45,50,55,60,65,70,75,80,100},{"F","C-","C","C+","B-","B","B+","A-","A","A+","Invalid Entry"}) -> A+ | I13: =LOOKUP(F13,{0,40,45,50,55,60,65,70,75,80,100},{0,2,2.25,2.5,2.75,3,3.25,3.5,3.75,4,"Invalid Entry"}) -> 4 | K13: 15 | L13: 66 | M13: 31 | N13: =SUM(K13,L13,IF(M13>29,10,IF(M13>26,9,IF(M13>23,8,IF(M13>20,7,IF(M13>17,6,0)))))) -> 91 | O13: 4 | P13: =LOOKUP(N13,{0,40,45,50,55,60,65,70,75,80,100},{"F","C-","C","C+","B-","B","B+","A-","A","A+","Invalid Entry"}) -> A+ | Q13: =LOOKUP(N13,{0,40,45,50,55,60,65,70,75,80,100},{0,2,2.25,2.5,2.75,3,3.25,3.5,3.75,4,"Invalid Entry"}) -> 4 | S13: 20 | T13: 66 | U13: 31 | V13: =SUM(S13,T13,IF(U13>29,10,IF(U13>26,9,IF(U13>23,8,IF(U13>20,7,IF(U13>17,6,0)))))) -> 96 | W13: 3 | X13: =LOOKUP(V13,{0,40,45,50,55,60,65,70,75,80,100},{"F","C-","C","C+","B-","B","B+","A-","A","A+","Invalid Entry"}) -> A+ | Y13: =LOOKUP(V13,{0,40,45,50,55,60,65,70,75,80,100},{0,2,2.25,2.5,2.75,3,3.25,3.5,3.75,4,"Invalid Entry"}) -> 4 | AA13: 13 | AB13: 66 | AC13: 31 | AD13: =SUM(AA13,AB13,IF(AC13>29,10,IF(AC13>26,9,IF(AC13>23,8,IF(AC13>20,7,IF(AC13>17,6,0)))))) -> 89 | AE13: 2 | AF13: =LOOKUP(AD13,{0,40,45,50,55,60,65,70,75,80,100},{"F","C-","C","C+","B-","B","B+","A-","A","A+","Invalid Entry"}) -> A+ | AG13: =LOOKUP(AD13,{0,40,45,50,55,60,65,70,75,80,100},{0,2,2.25,2.5,2.75,3,3.25,3.5,3.75,4,"Invalid Entry"}) -> 4 | AI13: =SUM(G13,O13,W13,AE13) -> 12 | AJ13: =ROUND(SUM(PRODUCT(I13,G13),PRODUCT(Q13,O13),PRODUCT(Y13,W13),PRODUCT(AG13,AE13))/AI13,2) -> 4 | AK13: =LOOKUP(AJ13,{0,2,2.25,2.5,2.75,3,3.25,3.5,3.75,4},{"F","C-","C","C+","B-","B","B+","A-","A","A+"}) -> A+
A14: 12 | B14: 2011236012 | C14: 19 | D14: 66 | E14: 29 | F14: =SUM(C14,D14,IF(E14>29,10,IF(E14>26,9,IF(E14>23,8,IF(E14>20,7,IF(E14>17,6,0)))))) -> 94 | G14: 3 | H14: =LOOKUP(F14,{0,40,45,50,55,60,65,70,75,80,100},{"F","C-","C","C+","B-","B","B+","A-","A","A+","Invalid Entry"}) -> A+ | I14: =LOOKUP(F14,{0,40,45,50,55,60,65,70,75,80,100},{0,2,2.25,2.5,2.75,3,3.25,3.5,3.75,4,"Invalid Entry"}) -> 4 | K14: 12 | L14: 66 | M14: 29 | N14: =SUM(K14,L14,IF(M14>29,10,IF(M14>26,9,IF(M14>23,8,IF(M14>20,7,IF(M14>17,6,0)))))) -> 87 | O14: 4 | P14: =LOOKUP(N14,{0,40,45,50,55,60,65,70,75,80,100},{"F","C-","C","C+","B-","B","B+","A-","A","A+","Invalid Entry"}) -> A+ | Q14: =LOOKUP(N14,{0,40,45,50,55,60,65,70,75,80,100},{0,2,2.25,2.5,2.75,3,3.25,3.5,3.75,4,"Invalid Entry"}) -> 4 | S14: 12 | T14: 66 | U14: 29 | V14: =SUM(S14,T14,IF(U14>29,10,IF(U14>26,9,IF(U14>23,8,IF(U14>20,7,IF(U14>17,6,0)))))) -> 87 | W14: 3 | X14: =LOOKUP(V14,{0,40,45,50,55,60,65,70,75,80,100},{"F","C-","C","C+","B-","B","B+","A-","A","A+","Invalid Entry"}) -> A+ | Y14: =LOOKUP(V14,{0,40,45,50,55,60,65,70,75,80,100},{0,2,2.25,2.5,2.75,3,3.25,3.5,3.75,4,"Invalid Entry"}) -> 4 | AA14: 12 | AB14: 66 | AC14: 29 | AD14: =SUM(AA14,AB14,IF(AC14>29,10,IF(AC14>26,9,IF(AC14>23,8,IF(AC14>20,7,IF(AC14>17,6,0)))))) -> 87 | AE14: 2 | AF14: =LOOKUP(AD14,{0,40,45,50,55,60,65,70,75,80,100},{"F","C-","C","C+","B-","B","B+","A-","A","A+","Invalid Entry"}) -> A+ | AG14: =LOOKUP(AD14,{0,40,45,50,55,60,65,70,75,80,100},{0,2,2.25,2.5,2.75,3,3.25,3.5,3.75,4,"Invalid Entry"}) -> 4 | AI14: =SUM(G14,O14,W14,AE14) -> 12 | AJ14: =ROUND(SUM(PRODUCT(I14,G14),PRODUCT(Q14,O14),PRODUCT(Y14,W14),PRODUCT(AG14,AE14))/AI14,2) -> 4 | AK14: =LOOKUP(AJ14,{0,2,2.25,2.5,2.75,3,3.25,3.5,3.75,4},{"F","C-","C","C+","B-","B","B+","A-","A","A+"}) -> A+
... A32: 30 | B32: 2011236030 | C32: 19 | D32: 46 | E32: 27 | F32: =SUM(C32,D32,IF(E32>29,10,IF(E32>26,9,IF(E32>23,8,IF(E32>20,7,IF(E32>17,6,0)))))) -> 74 | G32: 3 | H32: =LOOKUP(F32,{0,40,45,50,55,60,65,70,75,80,100},{"F","C-","C","C+","B-","B","B+","A-","A","A+","Invalid Entry"}) -> A- | I32: =LOOKUP(F32,{0,40,45,50,55,60,65,70,75,80,100},{0,2,2.25,2.5,2.75,3,3.25,3.5,3.75,4,"Invalid Entry"}) -> 3.5 | K32: 12 | L32: 46 | M32: 27 | N32: =SUM(K32,L32,IF(M32>29,10,IF(M32>26,9,IF(M32>23,8,IF(M32>20,7,IF(M32>17,6,0)))))) -> 67 | O32: 4 | P32: =LOOKUP(N32,{0,40,45,50,55,60,65,70,75,80,100},{"F","C-","C","C+","B-","B","B+","A-","A","A+","Invalid Entry"}) -> B+ | Q32: =LOOKUP(N32,{0,40,45,50,55,60,65,70,75,80,100},{0,2,2.25,2.5,2.75,3,3.25,3.5,3.75,4,"Invalid Entry"}) -> 3.25 | S32: 12 | T32: 46 | U32: 27 | V32: =SUM(S32,T32,IF(U32>29,10,IF(U32>26,9,IF(U32>23,8,IF(U32>20,7,IF(U32>17,6,0)))))) -> 67 | W32: 3 | X32: =LOOKUP(V32,{0,40,45,50,55,60,65,70,75,80,100},{"F","C-","C","C+","B-","B","B+","A-","A","A+","Invalid Entry"}) -> B+ | Y32: =LOOKUP(V32,{0,40,45,50,55,60,65,70,75,80,100},{0,2,2.25,2.5,2.75,3,3.25,3.5,3.75,4,"Invalid Entry"}) -> 3.25 | AA32: 11 | AB32: 46 | AC32: 27 | AD32: =SUM(AA32,AB32,IF(AC32>29,10,IF(AC32>26,9,IF(AC32>23,8,IF(AC32>20,7,IF(AC32>17,6,0)))))) -> 66 | AE32: 2 | AF32: =LOOKUP(AD32,{0,40,45,50,55,60,65,70,75,80,100},{"F","C-","C","C+","B-","B","B+","A-","A","A+","Invalid Entry"}) -> B+ | AG32: =LOOKUP(AD32,{0,40,45,50,55,60,65,70,75,80,100},{0,2,2.25,2.5,2.75,3,3.25,3.5,3.75,4,"Invalid Entry"}) -> 3.25 | AI32: =SUM(G32,O32,W32,AE32) -> 12 | AJ32: =ROUND(SUM(PRODUCT(I32,G32),PRODUCT(Q32,O32),PRODUCT(Y32,W32),PRODUCT(AG32,AE32))/AI32,2) -> 3.31 | AK32: =LOOKUP(AJ32,{0,2,2.25,2.5,2.75,3,3.25,3.5,3.75,4},{"F","C-","C","C+","B-","B","B+","A-","A","A+"}) -> B+

Sheet 2nd Semester
C1: =CourseList!B6 -> ENG-211 | K1: =CourseList!B7 -> ENG-213 | S1: =CourseList!B8 -> ENG-215 | AA1: =CourseList!B9 -> ENG-217 | AI1: Total Credit | AJ1: Total GPA | AK1: Letter Grade
A2: Serial | B2: {=StudentList!B1:B31} -> Student ID | C2: TT (20) | D2: Final (70) | E2: Attendence (33) | F2: Total | G2: Credit | H2: Letter Grade | I2: GPA | K2: TT (20) | L2: Final (70) | M2: Attendence (33) | N2: Total | O2: Credit | P2: Letter Grade | Q2: GPA | S2: TT (20) | T2: Final (70) | U2: Attendence (33) | V2: Total | W2: Credit | X2: Letter Grade | Y2: GPA | AA2: TT (20) | AB2: Final (70) | AC2: Attendence (33) | AD2: Total | AE2: Credit | AF2: Letter Grade | AG2: GPA
A3: 1 | B3: 2011236001 | C3: 20 | D3: 60 | E3: 30 | F3: =SUM(C3,D3,IF(E3>29,10,IF(E3>26,9,IF(E3>23,8,IF(E3>20,7,IF(E3>17,6,0)))))) -> 90 | G3: 4 | H3: =LOOKUP(F3,{0,40,45,50,55,60,65,70,75,80,100},{"F","C-","C","C+","B-","B","B+","A-","A","A+","Invalid Entry"}) -> A+ | I3: =LOOKUP(F3,{0,40,45,50,55,60,65,70,75,80,100},{0,2,2.25,2.5,2.75,3,3.25,3.5,3.75,4,"Invalid Entry"}) -> 4 | K3: 19 | L3: 53 | M3: 30 | N3: =SUM(K3,L3,IF(M3>29,10,IF(M3>26,9,IF(M3>23,8,IF(M3>20,7,IF(M3>17,6,0)))))) -> 82 | O3: 3 | P3: =LOOKUP(N3,{0,40,45,50,55,60,65,70,75,80,100},{"F","C-","C","C+","B-","B","B+","A-","A","A+","Invalid Entry"}) -> A+ | Q3: =LOOKUP(N3,{0,40,45,50,55,60,65,70,75,80,100},{0,2,2.25,2.5,2.75,3,3.25,3.5,3.75,4,"Invalid Entry"}) -> 4 | S3: 20 | T3: 55 | U3: 30 | V3: =SUM(S3,T3,IF(U3>29,10,IF(U3>26,9,IF(U3>23,8,IF(U3>20,7,IF(U3>17,6,0)))))) -> 85 | W3: 4 | X3: =LOOKUP(V3,{0,40,45,50,55,60,65,70,75,80,100},{"F","C-","C","C+","B-","B","B+","A-","A","A+","Invalid Entry"}) -> A+ | Y3: =LOOKUP(V3,{0,40,45,50,55,60,65,70,75,80,100},{0,2,2.25,2.5,2.75,3,3.25,3.5,3.75,4,"Invalid Entry"}) -> 4 | AA3: 17 | AB3: 63 | AC3: 30 | AD3: =SUM(AA3,AB3,IF(AC3>29,10,IF(AC3>26,9,IF(AC3>23,8,IF(AC3>20,7,IF(AC3>17,6,0)))))) -> 90 | AE3: 2 | AF3: =LOOKUP(AD3,{0,40,45,50,55,60,65,70,75,80,100},{"F","C-","C","C+","B-","B","B+","A-","A","A+","Invalid Entry"}) -> A+ | AG3: =LOOKUP(AD3,{0,40,45,50,55,60,65,70,75,80,100},{0,2,2.25,2.5,2.75,3,3.25,3.5,3.75,4,"Invalid Entry"}) -> 4 | AI3: =SUM(G3,O3,W3,AE3) -> 13 | AJ3: =ROUND(SUM(PRODUCT(I3,G3),PRODUCT(Q3,O3),PRODUCT(Y3,W3),PRODUCT(AG3,AE3))/AI3,2) -> 4 | AK3: =LOOKUP(AJ3,{0,2,2.25,2.5,2.75,3,3.25,3.5,3.75,4},{"F","C-","C","C+","B-","B","B+","A-","A","A+"}) -> A+
A4: 2 | B4: 2011236002 | C4: 11 | D4: 62 | E4: 30 | F4: =SUM(C4,D4,IF(E4>29,10,IF(E4>26,9,IF(E4>23,8,IF(E4>20,7,IF(E4>17,6,0)))))) -> 83 | G4: 4 | H4: =LOOKUP(F4,{0,40,45,50,55,60,65,70,75,80,100},{"F","C-","C","C+","B-","B","B+","A-","A","A+","Invalid Entry"}) -> A+ | I4: =LOOKUP(F4,{0,40,45,50,55,60,65,70,75,80,100},{0,2,2.25,2.5,2.75,3,3.25,3.5,3.75,4,"Invalid Entry"}) -> 4 | K4: 12 | L4: 45 | M4: 30 | N4: =SUM(K4,L4,IF(M4>29,10,IF(M4>26,9,IF(M4>23,8,IF(M4>20,7,IF(M4>17,6,0)))))) -> 67 | O4: 3 | P4: =LOOKUP(N4,{0,40,45,50,55,60,65,70,75,80,100},{"F","C-","C","C+","B-","B","B+","A-","A","A+","Invalid Entry"}) -> B+ | Q4: =LOOKUP(N4,{0,40,45,50,55,60,65,70,75,80,100},{0,2,2.25,2.5,2.75,3,3.25,3.5,3.75,4,"Invalid Entry"}) -> 3.25 | S4: 15 | T4: 68 | U4: 30 | V4: =SUM(S4,T4,IF(U4>29,10,IF(U4>26,9,IF(U4>23,8,IF(U4>20,7,IF(U4>17,6,0)))))) -> 93 | W4: 4 | X4: =LOOKUP(V4,{0,40,45,50,55,60,65,70,75,80,100},{"F","C-","C","C+","B-","B","B+","A-","A","A+","Invalid Entry"}) -> A+ | Y4: =LOOKUP(V4,{0,40,45,50,55,60,65,70,75,80,100},{0,2,2.25,2.5,2.75,3,3.25,3.5,3.75,4,"Invalid Entry"}) -> 4 | AA4: 18 | AB4: 45 | AC4: 30 | AD4: =SUM(AA4,AB4,IF(AC4>29,10,IF(AC4>26,9,IF(AC4>23,8,IF(AC4>20,7,IF(AC4>17,6,0)))))) -> 73 | AE4: 2 | AF4: =LOOKUP(AD4,{0,40,45,50,55,60,65,70,75,80,100},{"F","C-","C","C+","B-","B","B+","A-","A","A+","Invalid Entry"}) -> A- | AG4: =LOOKUP(AD4,{0,40,45,50,55,60,65,70,75,80,100},{0,2,2.25,2.5,2.75,3,3.25,3.5,3.75,4,"Invalid Entry"}) -> 3.5 | AI4: =SUM(G4,O4,W4,AE4) -> 13 | AJ4: =ROUND(SUM(PRODUCT(I4,G4),PRODUCT(Q4,O4),PRODUCT(Y4,W4),PRODUCT(AG4,AE4))/AI4,2) -> 3.75 | AK4: =LOOKUP(AJ4,{0,2,2.25,2.5,2.75,3,3.25,3.5,3.75,4},{"F","C-","C","C+","B-","B","B+","A-","A","A+"}) -> A
A5: 3 | B5: 2011236003 | C5: 19 | D5: 65 | E5: 26 | F5: =SUM(C5,D5,IF(E5>29,10,IF(E5>26,9,IF(E5>23,8,IF(E5>20,7,IF(E5>17,6,0)))))) -> 92 | G5: 4 | H5: =LOOKUP(F5,{0,40,45,50,55,60,65,70,75,80,100},{"F","C-","C","C+","B-","B","B+","A-","A","A+","Invalid Entry"}) -> A+ | I5: =LOOKUP(F5,{0,40,45,50,55,60,65,70,75,80,100},{0,2,2.25,2.5,2.75,3,3.25,3.5,3.75,4,"Invalid Entry"}) -> 4 | K5: 13 | L5: 42 | M5: 26 | N5: =SUM(K5,L5,IF(M5>29,10,IF(M5>26,9,IF(M5>23,8,IF(M5>20,7,IF(M5>17,6,0)))))) -> 63 | O5: 3 | P5: =LOOKUP(N5,{0,40,45,50,55,60,65,70,75,80,100},{"F","C-","C","C+","B-","B","B+","A-","A","A+","Invalid Entry"}) -> B | Q5: =LOOKUP(N5,{0,40,45,50,55,60,65,70,75,80,100},{0,2,2.25,2.5,2.75,3,3.25,3.5,3.75,4,"Invalid Entry"}) -> 3 | S5: 20 | T5: 55 | U5: 26 | V5: =SUM(S5,T5,IF(U5>29,10,IF(U5>26,9,IF(U5>23,8,IF(U5>20,7,IF(U5>17,6,0)))))) -> 83 | W5: 4 | X5: =LOOKUP(V5,{0,40,45,50,55,60,65,70,75,80,100},{"F","C-","C","C+","B-","B","B+","A-","A","A+","Invalid Entry"}) -> A+ | Y5: =LOOKUP(V5,{0,40,45,50,55,60,65,70,75,80,100},{0,2,2.25,2.5,2.75,3,3.25,3.5,3.75,4,"Invalid Entry"}) -> 4 | AA5: 11 | AB5: 57 | AC5: 26 | AD5: =SUM(AA5,AB5,IF(AC5>29,10,IF(AC5>26,9,IF(AC5>23,8,IF(AC5>20,7,IF(AC5>17,6,0)))))) -> 76 | AE5: 2 | AF5: =LOOKUP(AD5,{0,40,45,50,55,60,65,70,75,80,100},{"F","C-","C","C+","B-","B","B+","A-","A","A+","Invalid Entry"}) -> A | AG5: =LOOKUP(AD5,{0,40,45,50,55,60,65,70,75,80,100},{0,2,2.25,2.5,2.75,3,3.25,3.5,3.75,4,"Invalid Entry"}) -> 3.75 | AI5: =SUM(G5,O5,W5,AE5) -> 13 | AJ5: =ROUND(SUM(PRODUCT(I5,G5),PRODUCT(Q5,O5),PRODUCT(Y5,W5),PRODUCT(AG5,AE5))/AI5,2) -> 3.73 | AK5: =LOOKUP(AJ5,{0,2,2.25,2.5,2.75,3,3.25,3.5,3.75,4},{"F","C-","C","C+","B-","B","B+","A-","A","A+"}) -> A-
A6: 4 | B6: 2011236004 | C6: 15 | D6: 60 | E6: 31 | F6: =SUM(C6,D6,IF(E6>29,10,IF(E6>26,9,IF(E6>23,8,IF(E6>20,7,IF(E6>17,6,0)))))) -> 85 | G6: 4 | H6: =LOOKUP(F6,{0,40,45,50,55,60,65,70,75,80,100},{"F","C-","C","C+","B-","B","B+","A-","A","A+","Invalid Entry"}) -> A+ | I6: =LOOKUP(F6,{0,40,45,50,55,60,65,70,75,80,100},{0,2,2.25,2.5,2.75,3,3.25,3.5,3.75,4,"Invalid Entry"}) -> 4 | K6: 14 | L6: 59 | M6: 31 | N6: =SUM(K6,L6,IF(M6>29,10,IF(M6>26,9,IF(M6>23,8,IF(M6>20,7,IF(M6>17,6,0)))))) -> 83 | O6: 3 | P6: =LOOKUP(N6,{0,40,45,50,55,60,65,70,75,80,100},{"F","C-","C","C+","B-","B","B+","A-","A","A+","Invalid Entry"}) -> A+ | Q6: =LOOKUP(N6,{0,40,45,50,55,60,65,70,75,80,100},{0,2,2.25,2.5,2.75,3,3.25,3.5,3.75,4,"Invalid Entry"}) -> 4 | S6: 10 | T6: 45 | U6: 31 | V6: =SUM(S6,T6,IF(U6>29,10,IF(U6>26,9,IF(U6>23,8,IF(U6>20,7,IF(U6>17,6,0)))))) -> 65 | W6: 4 | X6: =LOOKUP(V6,{0,40,45,50,55,60,65,70,75,80,100},{"F","C-","C","C+","B-","B","B+","A-","A","A+","Invalid Entry"}) -> B+ | Y6: =LOOKUP(V6,{0,40,45,50,55,60,65,70,75,80,100},{0,2,2.25,2.5,2.75,3,3.25,3.5,3.75,4,"Invalid Entry"}) -> 3.25 | AA6: 16 | AB6: 55 | AC6: 31 | AD6: =SUM(AA6,AB6,IF(AC6>29,10,IF(AC6>26,9,IF(AC6>23,8,IF(AC6>20,7,IF(AC6>17,6,0)))))) -> 81 | AE6: 2 | AF6: =LOOKUP(AD6,{0,40,45,50,55,60,65,70,75,80,100},{"F","C-","C","C+","B-","B","B+","A-","A","A+","Invalid Entry"}) -> A+ | AG6: =LOOKUP(AD6,{0,40,45,50,55,60,65,70,75,80,100},{0,2,2.25,2.5,2.75,3,3.25,3.5,3.75,4,"Invalid Entry"}) -> 4 | AI6: =SUM(G6,O6,W6,AE6) -> 13 | AJ6: =ROUND(SUM(PRODUCT(I6,G6),PRODUCT(Q6,O6),PRODUCT(Y6,W6),PRODUCT(AG6,AE6))/AI6,2) -> 3.77 | AK6: =LOOKUP(AJ6,{0,2,2.25,2.5,2.75,3,3.25,3.5,3.75,4},{"F","C-","C","C+","B-","B","B+","A-","A","A+"}) -> A
A7: 5 | B7: 2011236005 | C7: 19 | D7: 44 | E7: 25 | F7: =SUM(C7,D7,IF(E7>29,10,IF(E7>26,9,IF(E7>23,8,IF(E7>20,7,IF(E7>17,6,0)))))) -> 71 | G7: 4 | H7: =LOOKUP(F7,{0,40,45,50,55,60,65,70,75,80,100},{"F","C-","C","C+","B-","B","B+","A-","A","A+","Invalid Entry"}) -> A- | I7: =LOOKUP(F7,{0,40,45,50,55,60,65,70,75,80,100},{0,2,2.25,2.5,2.75,3,3.25,3.5,3.75,4,"Invalid Entry"}) -> 3.5 | K7: 19 | L7: 40 | M7: 25 | N7: =SUM(K7,L7,IF(M7>29,10,IF(M7>26,9,IF(M7>23,8,IF(M7>20,7,IF(M7>17,6,0)))))) -> 67 | O7: 3 | P7: =LOOKUP(N7,{0,40,45,50,55,60,65,70,75,80,100},{"F","C-","C","C+","B-","B","B+","A-","A","A+","Invalid Entry"}) -> B+ | Q7: =LOOKUP(N7,{0,40,45,50,55,60,65,70,75,80,100},{0,2,2.25,2.5,2.75,3,3.25,3.5,3.75,4,"Invalid Entry"}) -> 3.25 | S7: 17 | T7: 60 | U7: 25 | V7: =SUM(S7,T7,IF(U7>29,10,IF(U7>26,9,IF(U7>23,8,IF(U7>20,7,IF(U7>17,6,0)))))) -> 85 | W7: 4 | X7: =LOOKUP(V7,{0,40,45,50,55,60,65,70,75,80,100},{"F","C-","C","C+","B-","B","B+","A-","A","A+","Invalid Entry"}) -> A+ | Y7: =LOOKUP(V7,{0,40,45,50,55,60,65,70,75,80,100},{0,2,2.25,2.5,2.75,3,3.25,3.5,3.75,4,"Invalid Entry"}) -> 4 | AA7: 10 | AB7: 56 | AC7: 25 | AD7: =SUM(AA7,AB7,IF(AC7>29,10,IF(AC7>26,9,IF(AC7>23,8,IF(AC7>20,7,IF(AC7>17,6,0)))))) -> 74 | AE7: 2 | AF7: =LOOKUP(AD7,{0,40,45,50,55,60,65,70,75,80,100},{"F","C-","C","C+","B-","B","B+","A-","A","A+","Invalid Entry"}) -> A- | AG7: =LOOKUP(AD7,{0,40,45,50,55,60,65,70,75,80,100},{0,2,2.25,2.5,2.75,3,3.25,3.5,3.75,4,"Invalid Entry"}) -> 3.5 | AI7: =SUM(G7,O7,W7,AE7) -> 13 | AJ7: =ROUND(SUM(PRODUCT(I7,G7),PRODUCT(Q7,O7),PRODUCT(Y7,W7),PRODUCT(AG7,AE7))/AI7,2) -> 3.6 | AK7: =LOOKUP(AJ7,{0,2,2.25,2.5,2.75,3,3.25,3.5,3.75,4},{"F","C-","C","C+","B-","B","B+","A-","A","A+"}) -> A-
A8: 6 | B8: 2011236006 | C8: 14 | D8: 53 | E8: 21 | F8: =SUM(C8,D8,IF(E8>29,10,IF(E8>26,9,IF(E8>23,8,IF(E8>20,7,IF(E8>17,6,0)))))) -> 74 | G8: 4 | H8: =LOOKUP(F8,{0,40,45,50,55,60,65,70,75,80,100},{"F","C-","C","C+","B-","B","B+","A-","A","A+","Invalid Entry"}) -> A- | I8: =LOOKUP(F8,{0,40,45,50,55,60,65,70,75,80,100},{0,2,2.25,2.5,2.75,3,3.25,3.5,3.75,4,"Invalid Entry"}) -> 3.5 | K8: 18 | L8: 57 | M8: 21 | N8: =SUM(K8,L8,IF(M8>29,10,IF(M8>26,9,IF(M8>23,8,IF(M8>20,7,IF(M8>17,6,0)))))) -> 82 | O8: 3 | P8: =LOOKUP(N8,{0,40,45,50,55,60,65,70,75,80,100},{"F","C-","C","C+","B-","B","B+","A-","A","A+","Invalid Entry"}) -> A+ | Q8: =LOOKUP(N8,{0,40,45,50,55,60,65,70,75,80,100},{0,2,2.25,2.5,2.75,3,3.25,3.5,3.75,4,"Invalid Entry"}) -> 4 | S8: 13 | T8: 65 | U8: 21 | V8: =SUM(S8,T8,IF(U8>29,10,IF(U8>26,9,IF(U8>23,8,IF(U8>20,7,IF(U8>17,6,0)))))) -> 85 | W8: 4 | X8: =LOOKUP(V8,{0,40,45,50,55,60,65,70,75,80,100},{"F","C-","C","C+","B-","B","B+","A-","A","A+","Invalid Entry"}) -> A+ | Y8: =LOOKUP(V8,{0,40,45,50,55,60,65,70,75,80,100},{0,2,2.25,2.5,2.75,3,3.25,3.5,3.75,4,"Invalid Entry"}) -> 4 | AA8: 14 | AB8: 62 | AC8: 21 | AD8: =SUM(AA8,AB8,IF(AC8>29,10,IF(AC8>26,9,IF(AC8>23,8,IF(AC8>20,7,IF(AC8>17,6,0)))))) -> 83 | AE8: 2 | AF8: =LOOKUP(AD8,{0,40,45,50,55,60,65,70,75,80,100},{"F","C-","C","C+","B-","B","B+","A-","A","A+","Invalid Entry"}) -> A+ | AG8: =LOOKUP(AD8,{0,40,45,50,55,60,65,70,75,80,100},{0,2,2.25,2.5,2.75,3,3.25,3.5,3.75,4,"Invalid Entry"}) -> 4 | AI8: =SUM(G8,O8,W8,AE8) -> 13 | AJ8: =ROUND(SUM(PRODUCT(I8,G8),PRODUCT(Q8,O8),PRODUCT(Y8,W8),PRODUCT(AG8,AE8))/AI8,2) -> 3.85 | AK8: =LOOKUP(AJ8,{0,2,2.25,2.5,2.75,3,3.25,3.5,3.75,4},{"F","C-","C","C+","B-","B","B+","A-","A","A+"}) -> A
A9: 7 | B9: 2011236007 | C9: 10 | D9: 62 | E9: 31 | F9: =SUM(C9,D9,IF(E9>29,10,IF(E9>26,9,IF(E9>23,8,IF(E9>20,7,IF(E9>17,6,0)))))) -> 82 | G9: 4 | H9: =LOOKUP(F9,{0,40,45,50,55,60,65,70,75,80,100},{"F","C-","C","C+","B-","B","B+","A-","A","A+","Invalid Entry"}) -> A+ | I9: =LOOKUP(F9,{0,40,45,50,55,60,65,70,75,80,100},{0,2,2.25,2.5,2.75,3,3.25,3.5,3.75,4,"Invalid Entry"}) -> 4 | K9: 18 | L9: 59 | M9: 31 | N9: =SUM(K9,L9,IF(M9>29,10,IF(M9>26,9,IF(M9>23,8,IF(M9>20,7,IF(M9>17,6,0)))))) -> 87 | O9: 3 | P9: =LOOKUP(N9,{0,40,45,50,55,60,65,70,75,80,100},{"F","C-","C","C+","B-","B","B+","A-","A","A+","Invalid Entry"}) -> A+ | Q9: =LOOKUP(N9,{0,40,45,50,55,60,65,70,75,80,100},{0,2,2.25,2.5,2.75,3,3.25,3.5,3.75,4,"Invalid Entry"}) -> 4 | S9: 20 | T9: 49 | U9: 31 | V9: =SUM(S9,T9,IF(U9>29,10,IF(U9>26,9,IF(U9>23,8,IF(U9>20,7,IF(U9>17,6,0)))))) -> 79 | W9: 4 | X9: =LOOKUP(V9,{0,40,45,50,55,60,65,70,75,80,100},{"F","C-","C","C+","B-","B","B+","A-","A","A+","Invalid Entry"}) -> A | Y9: =LOOKUP(V9,{0,40,45,50,55,60,65,70,75,80,100},{0,2,2.25,2.5,2.75,3,3.25,3.5,3.75,4,"Invalid Entry"}) -> 3.75 | AA9: 5 | AB9: 54 | AC9: 31 | AD9: =SUM(AA9,AB9,IF(AC9>29,10,IF(AC9>26,9,IF(AC9>23,8,IF(AC9>20,7,IF(AC9>17,6,0)))))) -> 69 | AE9: 2 | AF9: =LOOKUP(AD9,{0,40,45,50,55,60,65,70,75,80,100},{"F","C-","C","C+","B-","B","B+","A-","A","A+","Invalid Entry"}) -> B+ | AG9: =LOOKUP(AD9,{0,40,45,50,55,60,65,70,75,80,100},{0,2,2.25,2.5,2.75,3,3.25,3.5,3.75,4,"Invalid Entry"}) -> 3.25 | AI9: =SUM(G9,O9,W9,AE9) -> 13 | AJ9: =ROUND(SUM(PRODUCT(I9,G9),PRODUCT(Q9,O9),PRODUCT(Y9,W9),PRODUCT(AG9,AE9))/AI9,2) -> 3.81 | AK9: =LOOKUP(AJ9,{0,2,2.25,2.5,2.75,3,3.25,3.5,3.75,4},{"F","C-","C","C+","B-","B","B+","A-","A","A+"}) -> A
A10: 8 | B10: 2011236008 | C10: 18 | D10: 68 | E10: 30 | F10: =SUM(C10,D10,IF(E10>29,10,IF(E10>26,9,IF(E10>23,8,IF(E10>20,7,IF(E10>17,6,0)))))) -> 96 | G10: 4 | H10: =LOOKUP(F10,{0,40,45,50,55,60,65,70,75,80,100},{"F","C-","C","C+","B-","B","B+","A-","A","A+","Invalid Entry"}) -> A+ | I10: =LOOKUP(F10,{0,40,45,50,55,60,65,70,75,80,100},{0,2,2.25,2.5,2.75,3,3.25,3.5,3.75,4,"Invalid Entry"}) -> 4 | K10: 15 | L10: 49 | M10: 30 | N10: =SUM(K10,L10,IF(M10>29,10,IF(M10>26,9,IF(M10>23,8,IF(M10>20,7,IF(M10>17,6,0)))))) -> 74 | O10: 3 | P10: =LOOKUP(N10,{0,40,45,50,55,60,65,70,75,80,100},{"F","C-","C","C+","B-","B","B+","A-","A","A+","Invalid Entry"}) -> A- | Q10: =LOOKUP(N10,{0,40,45,50,55,60,65,70,75,80,100},{0,2,2.25,2.5,2.75,3,3.25,3.5,3.75,4,"Invalid Entry"}) -> 3.5 | S10: 17 | T10: 70 | U10: 30 | V10: =SUM(S10,T10,IF(U10>29,10,IF(U10>26,9,IF(U10>23,8,IF(U10>20,7,IF(U10>17,6,0)))))) -> 97 | W10: 4 | X10: =LOOKUP(V10,{0,40,45,50,55,60,65,70,75,80,100},{"F","C-","C","C+","B-","B","B+","A-","A","A+","Invalid Entry"}) -> A+ | Y10: =LOOKUP(V10,{0,40,45,50,55,60,65,70,75,80,100},{0,2,2.25,2.5,2.75,3,3.25,3.5,3.75,4,"Invalid Entry"}) -> 4 | AA10: 7 | AB10: 51 | AC10: 30 | AD10: =SUM(AA10,AB10,IF(AC10>29,10,IF(AC10>26,9,IF(AC10>23,8,IF(AC10>20,7,IF(AC10>17,6,0)))))) -> 68 | AE10: 2 | AF10: =LOOKUP(AD10,{0,40,45,50,55,60,65,70,75,80,100},{"F","C-","C","C+","B-","B","B+","A-","A","A+","Invalid Entry"}) -> B+ | AG10: =LOOKUP(AD10,{0,40,45,50,55,60,65,70,75,80,100},{0,2,2.25,2.5,2.75,3,3.25,3.5,3.75,4,"Invalid Entry"}) -> 3.25 | AI10: =SUM(G10,O10,W10,AE10) -> 13 | AJ10: =ROUND(SUM(PRODUCT(I10,G10),PRODUCT(Q10,O10),PRODUCT(Y10,W10),PRODUCT(AG10,AE10))/AI10,2) -> 3.77 | AK10: =LOOKUP(AJ10,{0,2,2.25,2.5,2.75,3,3.25,3.5,3.75,4},{"F","C-","C","C+","B-","B","B+","A-","A","A+"}) -> A
A11: 9 | B11: 2011236009 | C11: 9 | D11: 40 | E11: 33 | F11: =SUM(C11,D11,IF(E11>29,10,IF(E11>26,9,IF(E11>23,8,IF(E11>20,7,IF(E11>17,6,0)))))) -> 59 | G11: 4 | H11: =LOOKUP(F11,{0,40,45,50,55,60,65,70,75,80,100},{"F","C-","C","C+","B-","B","B+","A-","A","A+","Invalid Entry"}) -> B- | I11: =LOOKUP(F11,{0,40,45,50,55,60,65,70,75,80,100},{0,2,2.25,2.5,2.75,3,3.25,3.5,3.75,4,"Invalid Entry"}) -> 2.75 | K11: 12 | L11: 50 | M11: 33 | N11: =SUM(K11,L11,IF(M11>29,10,IF(M11>26,9,IF(M11>23,8,IF(M11>20,7,IF(M11>17,6,0)))))) -> 72 | O11: 3 | P11: =LOOKUP(N11,{0,40,45,50,55,60,65,70,75,80,100},{"F","C-","C","C+","B-","B","B+","A-","A","A+","Invalid Entry"}) -> A- | Q11: =LOOKUP(N11,{0,40,45,50,55,60,65,70,75,80,100},{0,2,2.25,2.5,2.75,3,3.25,3.5,3.75,4,"Invalid Entry"}) -> 3.5 | S11: 13 | T11: 70 | U11: 33 | V11: =SUM(S11,T11,IF(U11>29,10,IF(U11>26,9,IF(U11>23,8,IF(U11>20,7,IF(U11>17,6,0)))))) -> 93 | W11: 4 | X11: =LOOKUP(V11,{0,40,45,50,55,60,65,70,75,80,100},{"F","C-","C","C+","B-","B","B+","A-","A","A+","Invalid Entry"}) -> A+ | Y11: =LOOKUP(V11,{0,40,45,50,55,60,65,70,75,80,100},{0,2,2.25,2.5,2.75,3,3.25,3.5,3.75,4,"Invalid Entry"}) -> 4 | AA11: 14 | AB11: 54 | AC11: 33 | AD11: =SUM(AA11,AB11,IF(AC11>29,10,IF(AC11>26,9,IF(AC11>23,8,IF(AC11>20,7,IF(AC11>17,6,0)))))) -> 78 | AE11: 2 | AF11: =LOOKUP(AD11,{0,40,45,50,55,60,65,70,75,80,100},{"F","C-","C","C+","B-","B","B+","A-","A","A+","Invalid Entry"}) -> A | AG11: =LOOKUP(AD11,{0,40,45,50,55,60,65,70,75,80,100},{0,2,2.25,2.5,2.75,3,3.25,3.5,3.75,4,"Invalid Entry"}) -> 3.75 | AI11: =SUM(G11,O11,W11,AE11) -> 13 | AJ11: =ROUND(SUM(PRODUCT(I11,G11),PRODUCT(Q11,O11),PRODUCT(Y11,W11),PRODUCT(AG11,AE11))/AI11,2) -> 3.46 | AK11: =LOOKUP(AJ11,{0,2,2.25,2.5,2.75,3,3.25,3.5,3.75,4},{"F","C-","C","C+","B-","B","B+","A-","A","A+"}) -> B+
A12: 10 | B12: 2011236010 | C12: 16 | D12: 63 | E12: 24 | F12: =SUM(C12,D12,IF(E12>29,10,IF(E12>26,9,IF(E12>23,8,IF(E12>20,7,IF(E12>17,6,0)))))) -> 87 | G12: 4 | H12: =LOOKUP(F12,{0,40,45,50,55,60,65,70,75,80,100},{"F","C-","C","C+","B-","B","B+","A-","A","A+","Invalid Entry"}) -> A+ | I12: =LOOKUP(F12,{0,40,45,50,55,60,65,70,75,80,100},{0,2,2.25,2.5,2.75,3,3.25,3.5,3.75,4,"Invalid Entry"}) -> 4 | K12: 10 | L12: 46 | M12: 24 | N12: =SUM(K12,L12,IF(M12>29,10,IF(M12>26,9,IF(M12>23,8,IF(M12>20,7,IF(M12>17,6,0)))))) -> 64 | O12: 3 | P12: =LOOKUP(N12,{0,40,45,50,55,60,65,70,75,80,100},{"F","C-","C","C+","B-","B","B+","A-","A","A+","Invalid Entry"}) -> B | Q12: =LOOKUP(N12,{0,40,45,50,55,60,65,70,75,80,100},{0,2,2.25,2.5,2.75,3,3.25,3.5,3.75,4,"Invalid Entry"}) -> 3 | S12: 15 | T12: 45 | U12: 24 | V12: =SUM(S12,T12,IF(U12>29,10,IF(U12>26,9,IF(U12>23,8,IF(U12>20,7,IF(U12>17,6,0)))))) -> 68 | W12: 4 | X12: =LOOKUP(V12,{0,40,45,50,55,60,65,70,75,80,100},{"F","C-","C","C+","B-","B","B+","A-","A","A+","Invalid Entry"}) -> B+ | Y12: =LOOKUP(V12,{0,40,45,50,55,60,65,70,75,80,100},{0,2,2.25,2.5,2.75,3,3.25,3.5,3.75,4,"Invalid Entry"}) -> 3.25 | AA12: 10 | AB12: 70 | AC12: 24 | AD12: =SUM(AA12,AB12,IF(AC12>29,10,IF(AC12>26,9,IF(AC12>23,8,IF(AC12>20,7,IF(AC12>17,6,0)))))) -> 88 | AE12: 2 | AF12: =LOOKUP(AD12,{0,40,45,50,55,60,65,70,75,80,100},{"F","C-","C","C+","B-","B","B+","A-","A","A+","Invalid Entry"}) -> A+ | AG12: =LOOKUP(AD12,{0,40,45,50,55,60,65,70,75,80,100},{0,2,2.25,2.5,2.75,3,3.25,3.5,3.75,4,"Invalid Entry"}) -> 4 | AI12: =SUM(G12,O12,W12,AE12) -> 13 | AJ12: =ROUND(SUM(PRODUCT(I12,G12),PRODUCT(Q12,O12),PRODUCT(Y12,W12),PRODUCT(AG12,AE12))/AI12,2) -> 3.54 | AK12: =LOOKUP(AJ12,{0,2,2.25,2.5,2.75,3,3.25,3.5,3.75,4},{"F","C-","C","C+","B-","B","B+","A-","A","A+"}) -> A-
A13: 11 | B13: 2011236011 | C13: 16 | D13: 45 | E13: 31 | F13: =SUM(C13,D13,IF(E13>29,10,IF(E13>26,9,IF(E13>23,8,IF(E13>20,7,IF(E13>17,6,0)))))) -> 71 | G13: 4 | H13: =LOOKUP(F13,{0,40,45,50,55,60,65,70,75,80,100},{"F","C-","C","C+","B-","B","B+","A-","A","A+","Invalid Entry"}) -> A- | I13: =LOOKUP(F13,{0,40,45,50,55,60,65,70,75,80,100},{0,2,2.25,2.5,2.75,3,3.25,3.5,3.75,4,"Invalid Entry"}) -> 3.5 | K13: 15 | L13: 57 | M13: 31 | N13: =SUM(K13,L13,IF(M13>29,10,IF(M13>26,9,IF(M13>23,8,IF(M13>20,7,IF(M13>17,6,0)))))) -> 82 | O13: 3 | P13: =LOOKUP(N13,{0,40,45,50,55,60,65,70,75,80,100},{"F","C-","C","C+","B-","B","B+","A-","A","A+","Invalid Entry"}) -> A+ | Q13: =LOOKUP(N13,{0,40,45,50,55,60,65,70,75,80,100},{0,2,2.25,2.5,2.75,3,3.25,3.5,3.75,4,"Invalid Entry"}) -> 4 | S13: 20 | T13: 62 | U13: 31 | V13: =SUM(S13,T13,IF(U13>29,10,IF(U13>26,9,IF(U13>23,8,IF(U13>20,7,IF(U13>17,6,0)))))) -> 92 | W13: 4 | X13: =LOOKUP(V13,{0,40,45,50,55,60,65,70,75,80,100},{"F","C-","C","C+","B-","B","B+","A-","A","A+","Invalid Entry"}) -> A+ | Y13: =LOOKUP(V13,{0,40,45,50,55,60,65,70,75,80,100},{0,2,2.25,2.5,2.75,3,3.25,3.5,3.75,4,"Invalid Entry"}) -> 4 | AA13: 13 | AB13: 66 | AC13: 31 | AD13: =SUM(AA13,AB13,IF(AC13>29,10,IF(AC13>26,9,IF(AC13>23,8,IF(AC13>20,7,IF(AC13>17,6,0)))))) -> 89 | AE13: 2 | AF13: =LOOKUP(AD13,{0,40,45,50,55,60,65,70,75,80,100},{"F","C-","C","C+","B-","B","B+","A-","A","A+","Invalid Entry"}) -> A+ | AG13: =LOOKUP(AD13,{0,40,45,50,55,60,65,70,75,80,100},{0,2,2.25,2.5,2.75,3,3.25,3.5,3.75,4,"Invalid Entry"}) -> 4 | AI13: =SUM(G13,O13,W13,AE13) -> 13 | AJ13: =ROUND(SUM(PRODUCT(I13,G13),PRODUCT(Q13,O13),PRODUCT(Y13,W13),PRODUCT(AG13,AE13))/AI13,2) -> 3.85 | AK13: =LOOKUP(AJ13,{0,2,2.25,2.5,2.75,3,3.25,3.5,3.75,4},{"F","C-","C","C+","B-","B","B+","A-","A","A+"}) -> A
